Workbook

Sheet IN x Localidad NATI
A1: Programas provinciales - Dirección General de Vivienda
A2: Ingreso de Datos
C3: LOCALIDAD: | D3: Olaeta | E3: ⬅️ solamente ELEGIR LOCALIDAD
C4: DEPARTAMENTO: | D4: =IFERROR(VLOOKUP($D$3,'Base TOTAL'!A:AJ,2,0), "Sin dato") -> Juárez Celman
C5: Datos actuales | D5: Modificar/Ingresar nuevo dato
A6: PROGRAMA PROVINCIAL DE CORDÓN CUNETA Y ADOQUINES - LEY Nº 11089
B7: EXPEDIENTE N° | C7: =LET(res, IFERROR(VLOOKUP($D$3,'Base TOTAL'!A:AJ,3,0),""), IF(res="", "Sin datos", res)) -> 0423-080117/2026
B8: N° Orden | C8: =LET(res, IFERROR(VLOOKUP($D$3,'Base TOTAL'!A:AJ,4,0),""), IF(res="", "Sin datos", res)) -> 42
B9: MUNICIPIO / COMUNA | C9: =LET(res, IFERROR(VLOOKUP($D$3,'Base TOTAL'!A:AJ,5,0),""), IF(res="", "Sin datos", res)) -> M
B10: INTENDENTE / PRESIDENTE COMUNAL | C10: =LET(res, IFERROR(VLOOKUP($D$3,'Base TOTAL'!A:AJ,6,0),""), IF(res="", "Sin datos", res)) -> Gaston Bravo
B11: N° TELÉFONO M/C | C11: =LET(res, IFERROR(VLOOKUP($D$3,'Base TOTAL'!A:AJ,7,0),""), IF(res="", "Sin datos", res)) -> 3586543232
B12: CORREO ELECTRÓNICO | C12: =LET(res, IFERROR(VLOOKUP($D$3,'Base TOTAL'!A:AJ,8,0),""), IF(res="", "Sin datos", res)) -> arquitecturaolaeta@gmail.com
B13: CONTACTO TÉCNICO de M/C | C13: =LET(res, IFERROR(VLOOKUP($D$3,'Base TOTAL'!A:AJ,9,0),""), IF(res="", "Sin datos", res)) -> arquitecturaolaeta@gmail.com
A14: CONVENIO | B14: MONTO CONVENIO | C14: =LET(res, IFERROR(VLOOKUP($D$3,'Base TOTAL'!A:AJ,10,0),""), IF(res="", "Sin datos", res)) -> 180000000
B15: Cordón Cuneta (ml) | C15: =LET(res, IFERROR(VLOOKUP($D$3,'Base TOTAL'!A:AJ,11,0),""), IF(res="", "Sin datos", res)) -> 496
B16: Adoquinado (m2) | C16: =LET(res, IFERROR(VLOOKUP($D$3,'Base TOTAL'!A:AJ,12,0),""), IF(res="", "Sin datos", res)) -> 3200
A17: DOCUMENTACIÓN A PRESENTAR por Municipio / Comuna | B17: 1 | C17: =LET(res, IFERROR(VLOOKUP($D$3,'Base TOTAL'!A:AJ,13,0),""), IF(res="", "Sin datos", res)) -> A corregir por M/C
B18: 2 | C18: =LET(res, IFERROR(VLOOKUP($D$3,'Base TOTAL'!A:AJ,14,0),""), IF(res="", "Sin datos", res)) -> Completo OK
B19: 3 | C19: =LET(res, IFERROR(VLOOKUP($D$3,'Base TOTAL'!A:AJ,15,0),""), IF(res="", "Sin datos", res)) -> Completo OK
B20: 4 | C20: =LET(res, IFERROR(VLOOKUP($D$3,'Base TOTAL'!A:AJ,16,0),""), IF(res="", "Sin datos", res)) -> A corregir por M/C
B21: Descripción General | C21: =LET(res, IFERROR(VLOOKUP($D$3,'Base TOTAL'!A:AJ,17,0),""), IF(res="", "Sin datos", res)) -> A corregir por M/C
B22: Memoria Técnica | C22: =LET(res, IFERROR(VLOOKUP($D$3,'Base TOTAL'!A:AJ,18,0),""), IF(res="", "Sin datos", res)) -> A corregir por M/C
B23: Plazo de Ejecución | C23: =LET(res, IFERROR(VLOOKUP($D$3,'Base TOTAL'!A:AJ,19,0),""), IF(res="", "Sin datos", res)) -> Completo OK
B24: Cómputo y Presupuesto | C24: =LET(res, IFERROR(VLOOKUP($D$3,'Base TOTAL'!A:AJ,20,0),""), IF(res="", "Sin datos", res)) -> Completo OK
B25: Cronograma Avance Obra | C25: =LET(res, IFERROR(VLOOKUP($D$3,'Base TOTAL'!A:AJ,21,0),""), IF(res="", "Sin datos", res)) -> Completo OK
B26: Planimetría | C26: =LET(res, IFERROR(VLOOKUP($D$3,'Base TOTAL'!A:AJ,22,0),""), IF(res="", "Sin datos", res)) -> Completo OK
B27: Perfil Calzada | C27: =LET(res, IFERROR(VLOOKUP($D$3,'Base TOTAL'!A:AJ,23,0),""), IF(res="", "Sin datos", res)) -> A corregir por M/C
B28: Detalle de Cordón Cuneta | C28: =LET(res, IFERROR(VLOOKUP($D$3,'Base TOTAL'!A:AJ,24,0),""), IF(res="", "Sin datos", res)) -> Completo OK
B29: Detalle de Badén | C29: =LET(res, IFERROR(VLOOKUP($D$3,'Base TOTAL'!A:AJ,25,0),""), IF(res="", "Sin datos", res)) -> Completo OK
B30: Paquete estr. Calzada | C30: =LET(res, IFERROR(VLOOKUP($D$3,'Base TOTAL'!A:AJ,26,0),""), IF(res="", "Sin datos", res)) -> Completo OK
B31: 5 | C31: =LET(res, IFERROR(VLOOKUP($D$3,'Base TOTAL'!A:AJ,27,0),""), IF(res="", "Sin datos", res)) -> A corregir por M/C
B32: 6 | C32: =LET(res, IFERROR(VLOOKUP($D$3,'Base TOTAL'!A:AJ,28,0),""), IF(res="", "Sin datos", res)) -> Completo OK
B33: 7 | C33: =LET(res, IFERROR(VLOOKUP($D$3,'Base TOTAL'!A:AJ,29,0),""), IF(res="", "Sin datos", res)) -> Completo OK
B34: 8 | C34: =LET(res, IFERROR(VLOOKUP($D$3,'Base TOTAL'!A:AJ,30,0),""), IF(res="", "Sin datos", res)) -> Completo OK
B35: 9 | C35: =LET(res, IFERROR(VLOOKUP($D$3,'Base TOTAL'!A:AJ,31,0),""), IF(res="", "Sin datos", res)) -> A corregir por M/C
B36: ESTADO DEL EXPEDIENTE DE LA LOCALIDAD | C36: =LET(res, IFERROR(VLOOKUP($D$3,'Base TOTAL'!A:AJ,32,0),""), IF(res="", "Sin datos", res)) -> En CURSO en DGV
A37: OBSERVACIONES | C37: =LET(res, IFERROR(VLOOKUP($D$3,'Base TOTAL'!A:AJ,33,0),""), IF(res="", "Sin datos", res)) -> 13/7/2026: Comunicaciòn con la arq. a cargo. Se hacen observaciones sobre doc. tècnica a corregir. 08/7/2026: Se envìa al municipio (por Email) las correcciones que deben realizar. 03/7/2026: Presentan documentaciòn en Evaluaciòn. 19/6/26: El municipio presenta documentación a corregir y completar. Se envía INSTRUCTIVO de la documentación legar y técnica requerida. 5/6/26: Ingresa Nota Ministerio Gobierno autorizando financiamiento.
A38: EXPEDIENTE RADICADO EN: | B38: FECHA | C38: =LET(res, IFERROR(VLOOKUP($D$3,'Base TOTAL'!A:AJ,34,0),""), IF(res="", "Sin datos", res)) -> 46192
B39: REPARTICIÓN | C39: =LET(res, IFERROR(VLOOKUP($D$3,'Base TOTAL'!A:AJ,35,0),""), IF(res="", "Sin datos", res)) -> Técnica DGV
A40: PROGRAMA CÓRDOBA HOGAR - LEY Nº 8663
...

Sheet IN x Localidad PABLO
A1: Programas provinciales - Dirección General de Vivienda
A2: Ingreso de Datos
C3: LOCALIDAD: | D3: Las Playas | E3: ⬅️ solamente ELEGIR LOCALIDAD
C4: DEPARTAMENTO: | D4: =IFERROR(VLOOKUP($D$3,'Base TOTAL'!A:AJ,2,0), "Sin dato") -> Cruz del Eje
C5: Datos actuales | D5: Modificar/Ingresar nuevo dato
A6: PROGRAMA PROVINCIAL DE CORDÓN CUNETA Y ADOQUINES - LEY Nº 11089
B7: EXPEDIENTE N° | C7: =LET(res, IFERROR(VLOOKUP($D$3,'Base TOTAL'!A:AJ,3,0),""), IF(res="", "Sin datos", res)) -> 0423-079112/2026
B8: N° Orden | C8: =LET(res, IFERROR(VLOOKUP($D$3,'Base TOTAL'!A:AJ,4,0),""), IF(res="", "Sin datos", res)) -> 8
B9: MUNICIPIO / COMUNA | C9: =LET(res, IFERROR(VLOOKUP($D$3,'Base TOTAL'!A:AJ,5,0),""), IF(res="", "Sin datos", res)) -> C
B10: INTENDENTE / PRESIDENTE COMUNAL | C10: =LET(res, IFERROR(VLOOKUP($D$3,'Base TOTAL'!A:AJ,6,0),""), IF(res="", "Sin datos", res)) -> MARÍA DANIELA GODOY
B11: N° TELÉFONO M/C | C11: =LET(res, IFERROR(VLOOKUP($D$3,'Base TOTAL'!A:AJ,7,0),""), IF(res="", "Sin datos", res)) -> (3549) 46-8032
B12: CORREO ELECTRÓNICO | C12: =LET(res, IFERROR(VLOOKUP($D$3,'Base TOTAL'!A:AJ,8,0),""), IF(res="", "Sin datos", res)) -> Danielagodoy79@gmail.com
B13: CONTACTO TÉCNICO de M/C | C13: =LET(res, IFERROR(VLOOKUP($D$3,'Base TOTAL'!A:AJ,9,0),""), IF(res="", "Sin datos", res)) -> Ing. Bracamonte 3521401659 ---ingbracamontegustavo@gmail.com
A14: CONVENIO | B14: MONTO CONVENIO | C14: =LET(res, IFERROR(VLOOKUP($D$3,'Base TOTAL'!A:AJ,10,0),""), IF(res="", "Sin datos", res)) -> 200000000
B15: Cordón Cuneta (ml) | C15: =LET(res, IFERROR(VLOOKUP($D$3,'Base TOTAL'!A:AJ,11,0),""), IF(res="", "Sin datos", res)) -> Sin datos
B16: Adoquinado (m2) | C16: =LET(res, IFERROR(VLOOKUP($D$3,'Base TOTAL'!A:AJ,12,0),""), IF(res="", "Sin datos", res)) -> 3922.22
A17: DOCUMENTACIÓN A PRESENTAR por Municipio / Comuna | B17: 1 | C17: =LET(res, IFERROR(VLOOKUP($D$3,'Base TOTAL'!A:AJ,13,0),""), IF(res="", "Sin datos", res)) -> A corregir por M/C
B18: 2 | C18: =LET(res, IFERROR(VLOOKUP($D$3,'Base TOTAL'!A:AJ,14,0),""), IF(res="", "Sin datos", res)) -> Completo OK
B19: 3 | C19: =LET(res, IFERROR(VLOOKUP($D$3,'Base TOTAL'!A:AJ,15,0),""), IF(res="", "Sin datos", res)) -> Completo OK
B20: 4 | C20: =LET(res, IFERROR(VLOOKUP($D$3,'Base TOTAL'!A:AJ,16,0),""), IF(res="", "Sin datos", res)) -> A corregir por M/C
B21: Descripción General | C21: =LET(res, IFERROR(VLOOKUP($D$3,'Base TOTAL'!A:AJ,17,0),""), IF(res="", "Sin datos", res)) -> A corregir por M/C
B22: Memoria Técnica | C22: =LET(res, IFERROR(VLOOKUP($D$3,'Base TOTAL'!A:AJ,18,0),""), IF(res="", "Sin datos", res)) -> A corregir por M/C
B23: Plazo de Ejecución | C23: =LET(res, IFERROR(VLOOKUP($D$3,'Base TOTAL'!A:AJ,19,0),""), IF(res="", "Sin datos", res)) -> A corregir por M/C
B24: Cómputo y Presupuesto | C24: =LET(res, IFERROR(VLOOKUP($D$3,'Base TOTAL'!A:AJ,20,0),""), IF(res="", "Sin datos", res)) -> A corregir por M/C
B25: Cronograma Avance Obra | C25: =LET(res, IFERROR(VLOOKUP($D$3,'Base TOTAL'!A:AJ,21,0),""), IF(res="", "Sin datos", res)) -> Sin Presentar
B26: Planimetría | C26: =LET(res, IFERROR(VLOOKUP($D$3,'Base TOTAL'!A:AJ,22,0),""), IF(res="", "Sin datos", res)) -> A corregir por M/C
B27: Perfil Calzada | C27: =LET(res, IFERROR(VLOOKUP($D$3,'Base TOTAL'!A:AJ,23,0),""), IF(res="", "Sin datos", res)) -> A corregir por M/C
B28: Detalle de Cordón Cuneta | C28: =LET(res, IFERROR(VLOOKUP($D$3,'Base TOTAL'!A:AJ,24,0),""), IF(res="", "Sin datos", res)) -> Sin Presentar
B29: Detalle de Badén | C29: =LET(res, IFERROR(VLOOKUP($D$3,'Base TOTAL'!A:AJ,25,0),""), IF(res="", "Sin datos", res)) -> Sin Presentar
B30: Paquete estr. Calzada | C30: =LET(res, IFERROR(VLOOKUP($D$3,'Base TOTAL'!A:AJ,26,0),""), IF(res="", "Sin datos", res)) -> A corregir por M/C
B31: 5 | C31: =LET(res, IFERROR(VLOOKUP($D$3,'Base TOTAL'!A:AJ,27,0),""), IF(res="", "Sin datos", res)) -> Completo OK
B32: 6 | C32: =LET(res, IFERROR(VLOOKUP($D$3,'Base TOTAL'!A:AJ,28,0),""), IF(res="", "Sin datos", res)) -> Completo OK
B33: 7 | C33: =LET(res, IFERROR(VLOOKUP($D$3,'Base TOTAL'!A:AJ,29,0),""), IF(res="", "Sin datos", res)) -> Completo OK
B34: 8 | C34: =LET(res, IFERROR(VLOOKUP($D$3,'Base TOTAL'!A:AJ,30,0),""), IF(res="", "Sin datos", res)) -> Completo OK
B35: 9 | C35: =LET(res, IFERROR(VLOOKUP($D$3,'Base TOTAL'!A:AJ,31,0),""), IF(res="", "Sin datos", res)) -> Completo OK
B36: ESTADO DEL EXPEDIENTE DE LA LOCALIDAD | C36: =LET(res, IFERROR(VLOOKUP($D$3,'Base TOTAL'!A:AJ,32,0),""), IF(res="", "Sin datos", res)) -> En CURSO en DGV
A37: OBSERVACIONES | C37: =LET(res, IFERROR(VLOOKUP($D$3,'Base TOTAL'!A:AJ,33,0),""), IF(res="", "Sin datos", res)) -> 13-7-2026: Se recibe de la intend. doc. por whast y se solicita que se envie en base a instructivo y por E mail. 13-7-2026: Se llamo al ing. quien avisa que el viernes enviò la doc. a la municip y mañana la envian firmada 13/7/2026: Se solicita informen còmo van con la documentaciòn a presentar. 29/6/2026: Se enviaron por Email las observaciones A corregir por la comuna 26/6/26: Se envían las observaciones a corregir por el ing. Se aguardan las observaciones del area Legales........22/6/26: El ing. se comunica con el àrea tècnica: Se le envìa el Instructivo de la documentaciòn legal y tècnica a presentar. 19/6/26: Sin respuesta del ing. a cargo, se envìa nuevamente el instructivo a la Pres. comunal. 11/6/26: Se solicita corregir documentación presentada. SE LE ENVIÓ LOS 9 REQUISITOS PARA PARTICIPAR EN EL PROGRAMA
A38: EXPEDIENTE RADICADO EN: | B38: FECHA | C38: =LET(res, IFERROR(VLOOKUP($D$3,'Base TOTAL'!A:AJ,34,0),""), IF(res="", "Sin datos", res)) -> 46139
B39: REPARTICIÓN | C39: =LET(res, IFERROR(VLOOKUP($D$3,'Base TOTAL'!A:AJ,35,0),""), IF(res="", "Sin datos", res)) -> Técnica DGV
A40: PROGRAMA CÓRDOBA HOGAR - LEY Nº 8663
...

Sheet IN x Localidad H
A1: Programas provinciales - Dirección General de Vivienda
A2: Ingreso de Datos
C3: LOCALIDAD: | D3: Villa Sarmiento | E3: ⬅️ solamente ELEGIR LOCALIDAD
C4: DEPARTAMENTO: | D4: =IFERROR(VLOOKUP($D$3,'Base TOTAL'!A:AJ,2,0), "Sin dato") -> General Roca
C5: Datos actuales | D5: Modificar/Ingresar nuevo dato
A6: PROGRAMA PROVINCIAL DE CORDÓN CUNETA Y ADOQUINES - LEY Nº 11089
B7: EXPEDIENTE N° | C7: =LET(res, IFERROR(VLOOKUP($D$3,'Base TOTAL'!A:AJ,3,0),""), IF(res="", "Sin datos", res)) -> 0423-079096/2026
B8: N° Orden | C8: =LET(res, IFERROR(VLOOKUP($D$3,'Base TOTAL'!A:AJ,4,0),""), IF(res="", "Sin datos", res)) -> 14
B9: MUNICIPIO / COMUNA | C9: =LET(res, IFERROR(VLOOKUP($D$3,'Base TOTAL'!A:AJ,5,0),""), IF(res="", "Sin datos", res)) -> C
B10: INTENDENTE / PRESIDENTE COMUNAL | C10: =LET(res, IFERROR(VLOOKUP($D$3,'Base TOTAL'!A:AJ,6,0),""), IF(res="", "Sin datos", res)) -> OSVALDO ESTRADA
B11: N° TELÉFONO M/C | C11: =LET(res, IFERROR(VLOOKUP($D$3,'Base TOTAL'!A:AJ,7,0),""), IF(res="", "Sin datos", res)) -> (3583) 43-0074
B12: CORREO ELECTRÓNICO | C12: =LET(res, IFERROR(VLOOKUP($D$3,'Base TOTAL'!A:AJ,8,0),""), IF(res="", "Sin datos", res)) -> _
B13: CONTACTO TÉCNICO de M/C | C13: =LET(res, IFERROR(VLOOKUP($D$3,'Base TOTAL'!A:AJ,9,0),""), IF(res="", "Sin datos", res)) -> rojobufa@gmail.com
A14: CONVENIO | B14: MONTO CONVENIO | C14: =LET(res, IFERROR(VLOOKUP($D$3,'Base TOTAL'!A:AJ,10,0),""), IF(res="", "Sin datos", res)) -> 210000000
B15: Cordón Cuneta (ml) | C15: =LET(res, IFERROR(VLOOKUP($D$3,'Base TOTAL'!A:AJ,11,0),""), IF(res="", "Sin datos", res)) -> 1530
B16: Adoquinado (m2) | C16: =LET(res, IFERROR(VLOOKUP($D$3,'Base TOTAL'!A:AJ,12,0),""), IF(res="", "Sin datos", res)) -> 1575
A17: DOCUMENTACIÓN A PRESENTAR por Municipio / Comuna | B17: 1 | C17: =LET(res, IFERROR(VLOOKUP($D$3,'Base TOTAL'!A:AJ,13,0),""), IF(res="", "Sin datos", res)) -> Completo OK
B18: 2 | C18: =LET(res, IFERROR(VLOOKUP($D$3,'Base TOTAL'!A:AJ,14,0),""), IF(res="", "Sin datos", res)) -> Completo OK
B19: 3 | C19: =LET(res, IFERROR(VLOOKUP($D$3,'Base TOTAL'!A:AJ,15,0),""), IF(res="", "Sin datos", res)) -> A corregir por M/C
B20: 4 | C20: =LET(res, IFERROR(VLOOKUP($D$3,'Base TOTAL'!A:AJ,16,0),""), IF(res="", "Sin datos", res)) -> A corregir por M/C
B21: Descripción General | C21: =LET(res, IFERROR(VLOOKUP($D$3,'Base TOTAL'!A:AJ,17,0),""), IF(res="", "Sin datos", res)) -> Completo OK
B22: Memoria Técnica | C22: =LET(res, IFERROR(VLOOKUP($D$3,'Base TOTAL'!A:AJ,18,0),""), IF(res="", "Sin datos", res)) -> Completo OK
B23: Plazo de Ejecución | C23: =LET(res, IFERROR(VLOOKUP($D$3,'Base TOTAL'!A:AJ,19,0),""), IF(res="", "Sin datos", res)) -> Sin Presentar
B24: Cómputo y Presupuesto | C24: =LET(res, IFERROR(VLOOKUP($D$3,'Base TOTAL'!A:AJ,20,0),""), IF(res="", "Sin datos", res)) -> Completo OK
B25: Cronograma Avance Obra | C25: =LET(res, IFERROR(VLOOKUP($D$3,'Base TOTAL'!A:AJ,21,0),""), IF(res="", "Sin datos", res)) -> Completo OK
B26: Planimetría | C26: =LET(res, IFERROR(VLOOKUP($D$3,'Base TOTAL'!A:AJ,22,0),""), IF(res="", "Sin datos", res)) -> A corregir por M/C
B27: Perfil Calzada | C27: =LET(res, IFERROR(VLOOKUP($D$3,'Base TOTAL'!A:AJ,23,0),""), IF(res="", "Sin datos", res)) -> Sin Presentar
B28: Detalle de Cordón Cuneta | C28: =LET(res, IFERROR(VLOOKUP($D$3,'Base TOTAL'!A:AJ,24,0),""), IF(res="", "Sin datos", res)) -> Completo OK
B29: Detalle de Badén | C29: =LET(res, IFERROR(VLOOKUP($D$3,'Base TOTAL'!A:AJ,25,0),""), IF(res="", "Sin datos", res)) -> Completo OK
B30: Paquete estr. Calzada | C30: =LET(res, IFERROR(VLOOKUP($D$3,'Base TOTAL'!A:AJ,26,0),""), IF(res="", "Sin datos", res)) -> Completo OK
B31: 5 | C31: =LET(res, IFERROR(VLOOKUP($D$3,'Base TOTAL'!A:AJ,27,0),""), IF(res="", "Sin datos", res)) -> Completo OK
B32: 6 | C32: =LET(res, IFERROR(VLOOKUP($D$3,'Base TOTAL'!A:AJ,28,0),""), IF(res="", "Sin datos", res)) -> Completo OK
B33: 7 | C33: =LET(res, IFERROR(VLOOKUP($D$3,'Base TOTAL'!A:AJ,29,0),""), IF(res="", "Sin datos", res)) -> Completo OK
B34: 8 | C34: =LET(res, IFERROR(VLOOKUP($D$3,'Base TOTAL'!A:AJ,30,0),""), IF(res="", "Sin datos", res)) -> Completo OK
B35: 9 | C35: =LET(res, IFERROR(VLOOKUP($D$3,'Base TOTAL'!A:AJ,31,0),""), IF(res="", "Sin datos", res)) -> Completo OK
B36: ESTADO DEL EXPEDIENTE DE LA LOCALIDAD | C36: =LET(res, IFERROR(VLOOKUP($D$3,'Base TOTAL'!A:AJ,32,0),""), IF(res="", "Sin datos", res)) -> En CURSO en DGV
A37: OBSERVACIONES | C37: =LET(res, IFERROR(VLOOKUP($D$3,'Base TOTAL'!A:AJ,33,0),""), IF(res="", "Sin datos", res)) -> 03-07-2026 Completar: - Pto. 3 en Declarac. Jurada y.... Se deberà colocar las Geo Referenc. en los domicilios que figuren como (calle Publica sin Numero y tambien en los de Zona Rural) - En la Memoria pto. 3 colocar PLAZO de OBRA (Ver instruct.) -En ambas PLANIM. Generales colocar (Geo Referenc. y Medidas generales Largo y ancho de las calles del proyecto). - Presentar DETALLE Perfil Transversal de Calzada) Ver instructivo. - 30/6/2026: Se solicito por email envien imagen de DNI y CBU con mas definicion. el resto de la documentación esta completa. 19-06-2026- Se solicita al arq. Buffa ( 1CBU Y2 DNI borrosos + 3Sobre las Planim. Gral coloque las Geo Refer de los 3 sectores de obra + 4 faltan Perfil transv de calzada ) 12-06-2026 Se pidio al arq. R.Buffa estos faltantes + Georef. en pl. gral. --RTA.: 11-06-2026 de esta correc. solo faltan en TECNICA (agregar cortes transv. de calz. + detalle de paquete estr. de calz + detalles de cordones cun y badenes lo demas correcto) + en LEG ( en Nota contad pto 5 cambiar el plazo a 180 dias) -22-06-2026 - 04-06-2026 - Deben completar (Pto 4- graficos Detalles de Perfiles transv. de calzada + detalle graf. de cordon cuneta + secc transv. de de vaden + Pto. Nª 9 Acta de proclamac cantidad de votos?..Preguntar a Natalia) Ya ajustó los montos… Pasó $236.529.986,60 y debe ser de $210.000.000 - Debe cambiar Nota Inicial, dice plazo obra 365 días y debe decir 180 días El 29/05/26 ingresa nva. Nota digi 0697832111-126 (La parte técnica ya está ok - Pero falta cambiar: Plazo de Obra, en Nota inicial) YA LO CAMBIÓ Y ENVIÓ 29/5/26 El 26/05/26 se recibe nueva documentación. ¡Se excede del monto estipulado! Debe calcular ENVIÓ DOCUMENTACIÓN PARA SER ANALIZADA. El 12/5/26 se envía correcciones técnicas y documentación gráfica y planillas modelo, para realizar nueva presentación.
A38: EXPEDIENTE RADICADO EN: | B38: FECHA | C38: =LET(res, IFERROR(VLOOKUP($D$3,'Base TOTAL'!A:AJ,34,0),""), IF(res="", "Sin datos", res)) -> 46139
B39: REPARTICIÓN | C39: =LET(res, IFERROR(VLOOKUP($D$3,'Base TOTAL'!A:AJ,35,0),""), IF(res="", "Sin datos", res)) -> Técnica DGV
A40: PROGRAMA CÓRDOBA HOGAR - LEY Nº 8663
...

Sheet IN x Localidad BETINA
A1: Programas provinciales - Dirección General de Vivienda
A2: Ingreso de Datos
C3: LOCALIDAD: | D3: Los Reartes | E3: ⬅️ solamente ELEGIR LOCALIDAD
C4: DEPARTAMENTO: | D4: =IFERROR(VLOOKUP($D$3,'Base TOTAL'!A:AJ,2,0), "Sin dato") -> Calamuchita
C5: Datos actuales | D5: Modificar/Ingresar nuevo dato
A6: PROGRAMA PROVINCIAL DE CORDÓN CUNETA Y ADOQUINES - LEY Nº 11089
B7: EXPEDIENTE N° | C7: =LET(res, IFERROR(VLOOKUP($D$3,'Base TOTAL'!A:AJ,3,0),""), IF(res="", "Sin datos", res)) -> 0423-080115/2026
B8: N° Orden | C8: =LET(res, IFERROR(VLOOKUP($D$3,'Base TOTAL'!A:AJ,4,0),""), IF(res="", "Sin datos", res)) -> 39
B9: MUNICIPIO / COMUNA | C9: =LET(res, IFERROR(VLOOKUP($D$3,'Base TOTAL'!A:AJ,5,0),""), IF(res="", "Sin datos", res)) -> Sin datos
B10: INTENDENTE / PRESIDENTE COMUNAL | C10: =LET(res, IFERROR(VLOOKUP($D$3,'Base TOTAL'!A:AJ,6,0),""), IF(res="", "Sin datos", res)) -> Sin datos
B11: N° TELÉFONO M/C | C11: =LET(res, IFERROR(VLOOKUP($D$3,'Base TOTAL'!A:AJ,7,0),""), IF(res="", "Sin datos", res)) -> Sin datos
B12: CORREO ELECTRÓNICO | C12: =LET(res, IFERROR(VLOOKUP($D$3,'Base TOTAL'!A:AJ,8,0),""), IF(res="", "Sin datos", res)) -> inesramello@losreartes.gob.ar
B13: CONTACTO TÉCNICO de M/C | C13: =LET(res, IFERROR(VLOOKUP($D$3,'Base TOTAL'!A:AJ,9,0),""), IF(res="", "Sin datos", res)) -> Ing. Martin Gallo 351-6645348 Mail: martingallo2012@gmail.com
A14: CONVENIO | B14: MONTO CONVENIO | C14: =LET(res, IFERROR(VLOOKUP($D$3,'Base TOTAL'!A:AJ,10,0),""), IF(res="", "Sin datos", res)) -> 100000000
B15: Cordón Cuneta (ml) | C15: =LET(res, IFERROR(VLOOKUP($D$3,'Base TOTAL'!A:AJ,11,0),""), IF(res="", "Sin datos", res)) -> 418
B16: Adoquinado (m2) | C16: =LET(res, IFERROR(VLOOKUP($D$3,'Base TOTAL'!A:AJ,12,0),""), IF(res="", "Sin datos", res)) -> 1379
A17: DOCUMENTACIÓN A PRESENTAR por Municipio / Comuna | B17: 1 | C17: =LET(res, IFERROR(VLOOKUP($D$3,'Base TOTAL'!A:AJ,13,0),""), IF(res="", "Sin datos", res)) -> En Evaluaciòn Jurìdico
B18: 2 | C18: =LET(res, IFERROR(VLOOKUP($D$3,'Base TOTAL'!A:AJ,14,0),""), IF(res="", "Sin datos", res)) -> En Evaluaciòn Jurìdico
B19: 3 | C19: =LET(res, IFERROR(VLOOKUP($D$3,'Base TOTAL'!A:AJ,15,0),""), IF(res="", "Sin datos", res)) -> En Evaluaciòn Jurìdico
B20: 4 | C20: =LET(res, IFERROR(VLOOKUP($D$3,'Base TOTAL'!A:AJ,16,0),""), IF(res="", "Sin datos", res)) -> A corregir por M/C
B21: Descripción General | C21: =LET(res, IFERROR(VLOOKUP($D$3,'Base TOTAL'!A:AJ,17,0),""), IF(res="", "Sin datos", res)) -> A corregir por M/C
B22: Memoria Técnica | C22: =LET(res, IFERROR(VLOOKUP($D$3,'Base TOTAL'!A:AJ,18,0),""), IF(res="", "Sin datos", res)) -> A corregir por M/C
B23: Plazo de Ejecución | C23: =LET(res, IFERROR(VLOOKUP($D$3,'Base TOTAL'!A:AJ,19,0),""), IF(res="", "Sin datos", res)) -> A corregir por M/C
B24: Cómputo y Presupuesto | C24: =LET(res, IFERROR(VLOOKUP($D$3,'Base TOTAL'!A:AJ,20,0),""), IF(res="", "Sin datos", res)) -> A corregir por M/C
B25: Cronograma Avance Obra | C25: =LET(res, IFERROR(VLOOKUP($D$3,'Base TOTAL'!A:AJ,21,0),""), IF(res="", "Sin datos", res)) -> A corregir por M/C
B26: Planimetría | C26: =LET(res, IFERROR(VLOOKUP($D$3,'Base TOTAL'!A:AJ,22,0),""), IF(res="", "Sin datos", res)) -> A corregir por M/C
B27: Perfil Calzada | C27: =LET(res, IFERROR(VLOOKUP($D$3,'Base TOTAL'!A:AJ,23,0),""), IF(res="", "Sin datos", res)) -> A corregir por M/C
B28: Detalle de Cordón Cuneta | C28: =LET(res, IFERROR(VLOOKUP($D$3,'Base TOTAL'!A:AJ,24,0),""), IF(res="", "Sin datos", res)) -> A corregir por M/C
B29: Detalle de Badén | C29: =LET(res, IFERROR(VLOOKUP($D$3,'Base TOTAL'!A:AJ,25,0),""), IF(res="", "Sin datos", res)) -> A corregir por M/C
B30: Paquete estr. Calzada | C30: =LET(res, IFERROR(VLOOKUP($D$3,'Base TOTAL'!A:AJ,26,0),""), IF(res="", "Sin datos", res)) -> A corregir por M/C
B31: 5 | C31: =LET(res, IFERROR(VLOOKUP($D$3,'Base TOTAL'!A:AJ,27,0),""), IF(res="", "Sin datos", res)) -> En Evaluaciòn Jurìdico
B32: 6 | C32: =LET(res, IFERROR(VLOOKUP($D$3,'Base TOTAL'!A:AJ,28,0),""), IF(res="", "Sin datos", res)) -> En Evaluaciòn Jurìdico
B33: 7 | C33: =LET(res, IFERROR(VLOOKUP($D$3,'Base TOTAL'!A:AJ,29,0),""), IF(res="", "Sin datos", res)) -> En Evaluaciòn Jurìdico
B34: 8 | C34: =LET(res, IFERROR(VLOOKUP($D$3,'Base TOTAL'!A:AJ,30,0),""), IF(res="", "Sin datos", res)) -> En Evaluaciòn Jurìdico
B35: 9 | C35: =LET(res, IFERROR(VLOOKUP($D$3,'Base TOTAL'!A:AJ,31,0),""), IF(res="", "Sin datos", res)) -> En Evaluaciòn Jurìdico
B36: ESTADO DEL EXPEDIENTE DE LA LOCALIDAD | C36: =LET(res, IFERROR(VLOOKUP($D$3,'Base TOTAL'!A:AJ,32,0),""), IF(res="", "Sin datos", res)) -> En CURSO en DGV
A37: OBSERVACIONES | C37: =LET(res, IFERROR(VLOOKUP($D$3,'Base TOTAL'!A:AJ,33,0),""), IF(res="", "Sin datos", res)) -> 03/7/2026: Presentan documentación en evaluaciòn. 22/6/26:Comunicaciòn con la pres. comunal. Se envìa Instructivo de la documentaciòn legal y tècnica requerida al munic. y al profesional. . 5/6/26: Ingresa Nota Ministerio Gobierno autorizando financiamiento.
A38: EXPEDIENTE RADICADO EN: | B38: FECHA | C38: =LET(res, IFERROR(VLOOKUP($D$3,'Base TOTAL'!A:AJ,34,0),""), IF(res="", "Sin datos", res)) -> Sin datos
B39: REPARTICIÓN | C39: =LET(res, IFERROR(VLOOKUP($D$3,'Base TOTAL'!A:AJ,35,0),""), IF(res="", "Sin datos", res)) -> Sin datos
A40: PROGRAMA CÓRDOBA HOGAR - LEY Nº 8663
...

Sheet REP Depart.
A1: OBRA: "EJECUCIÒN DE CORDÒN CUNETA Y ADOQUINADO"
A2: PROGRAMA: "PROVINCIAL DE CORDÒN CUNETA Y ADOQUINES" - LEY Nº 11.089
A3: INFORME DEPARTAMENTO | B3: =TODAY() -> 46216
A4: DEPARTAMENTO: | B4: Marcos Juárez
A5: Cantidad de localidades afectadas | B5: =COUNTIF('Base TOTAL'!B:B, $B$4) -> 10
A6: TRAMITE PRE-OBRA
A7: MONTO TOTAL: | B7: =SUMIF('Base TOTAL'!B:B, $B$4, 'Base TOTAL'!J:J) -> 1420000000
A8: ='Base TOTAL'!K3 -> Cordón Cuneta (ml) | B8: =SUMIF('Base TOTAL'!B:B, $B$4, 'Base TOTAL'!K:K) -> 889
A9: ='Base TOTAL'!L3 -> Adoquinado (m2) | B9: =SUMIF('Base TOTAL'!B:B, $B$4, 'Base TOTAL'!L:L) -> 4520.9
A10: ='Base TOTAL'!AF3 -> ESTADO DEL EXPEDIENTE DE LA LOCALIDAD
A11: =IFERROR(__xludf.DUMMYFUNCTION("SORT(FILTER('Base TOTAL'!A:A, 'Base TOTAL'!B:B = B4))"),"Arias") -> Arias | B11: =IFERROR(VLOOKUP($A11,'Base TOTAL'!A:AJ,32,0), "-") -> En CURSO en DGV
A12: =IFERROR(__xludf.DUMMYFUNCTION("""COMPUTED_VALUE"""),"Camilo Aldao") -> Camilo Aldao | B12: =IFERROR(VLOOKUP($A12,'Base TOTAL'!A:AJ,32,0), "-") -> COMPLETO en DGV
A13: =IFERROR(__xludf.DUMMYFUNCTION("""COMPUTED_VALUE"""),"Capitán General Bernardo O'Higgins") -> Capitán General Bernardo O'Higgins | B13: =IFERROR(VLOOKUP($A13,'Base TOTAL'!A:AJ,32,0), "-") -> En CURSO en DGV
A14: =IFERROR(__xludf.DUMMYFUNCTION("""COMPUTED_VALUE"""),"Cavanagh") -> Cavanagh | B14: =IFERROR(VLOOKUP($A14,'Base TOTAL'!A:AJ,32,0), "-") -> En CURSO en DGV
A15: =IFERROR(__xludf.DUMMYFUNCTION("""COMPUTED_VALUE"""),"Colonia Barge") -> Colonia Barge | B15: =IFERROR(VLOOKUP($A15,'Base TOTAL'!A:AJ,32,0), "-") -> A INICIAR en DGV
A16: =IFERROR(__xludf.DUMMYFUNCTION("""COMPUTED_VALUE"""),"Colonia Italiana") -> Colonia Italiana | B16: =IFERROR(VLOOKUP($A16,'Base TOTAL'!A:AJ,32,0), "-") -> COMPLETO en DGV
A17: =IFERROR(__xludf.DUMMYFUNCTION("""COMPUTED_VALUE"""),"Cruz Alta") -> Cruz Alta | B17: =IFERROR(VLOOKUP($A17,'Base TOTAL'!A:AJ,32,0), "-") -> A INICIAR en DGV
A18: =IFERROR(__xludf.DUMMYFUNCTION("""COMPUTED_VALUE"""),"General Baldissera") -> General Baldissera | B18: =IFERROR(VLOOKUP($A18,'Base TOTAL'!A:AJ,32,0), "-") -> A INICIAR en DGV
A19: =IFERROR(__xludf.DUMMYFUNCTION("""COMPUTED_VALUE"""),"General Roca") -> General Roca | B19: =IFERROR(VLOOKUP($A19,'Base TOTAL'!A:AJ,32,0), "-") -> COMPLETO en DGV
A20: =IFERROR(__xludf.DUMMYFUNCTION("""COMPUTED_VALUE"""),"Saira") -> Saira | B20: =IFERROR(VLOOKUP($A20,'Base TOTAL'!A:AJ,32,0), "-") -> A INICIAR en DGV
B21: =IFERROR(VLOOKUP($A21,'Base TOTAL'!A:AJ,32,0), "-") -> -
B22: =IFERROR(VLOOKUP($A22,'Base TOTAL'!A:AJ,32,0), "-") -> -
B23: =IFERROR(VLOOKUP($A23,'Base TOTAL'!A:AJ,32,0), "-") -> -
B24: =IFERROR(VLOOKUP($A24,'Base TOTAL'!A:AJ,32,0), "-") -> -
B25: =IFERROR(VLOOKUP($A25,'Base TOTAL'!A:AJ,32,0), "-") -> -
B26: =IFERROR(VLOOKUP($A26,'Base TOTAL'!A:AJ,32,0), "-") -> -
B27: =IFERROR(VLOOKUP($A27,'Base TOTAL'!A:AJ,32,0), "-") -> -
B28: =IFERROR(VLOOKUP($A28,'Base TOTAL'!A:AJ,32,0), "-") -> -
B29: =IFERROR(VLOOKUP($A29,'Base TOTAL'!A:AJ,32,0), "-") -> -
B30: =IFERROR(VLOOKUP($A30,'Base TOTAL'!A:AJ,32,0), "-") -> -
B31: =IFERROR(VLOOKUP($A31,'Base TOTAL'!A:AJ,32,0), "-") -> -
B32: =IFERROR(VLOOKUP($A32,'Base TOTAL'!A:AJ,32,0), "-") -> -
... B50: =IFERROR(VLOOKUP($A50,'Base TOTAL'!A:AJ,32,0), "-") -> -
A51: fin del listado

Sheet REP Loc.
A1: OBRA: "EJECUCIÒN DE CORDÒN CUNETA Y ADOQUINADO"
A2: PROGRAMA: "PROVINCIAL DE CORDÒN CUNETA Y ADOQUINES" - LEY Nº 11.089
A3: INFORME LOCALIDAD | B3: =TODAY() -> 46216
A4: LOCALIDAD: | B4: Guanaco Muerto
A5: DEPARTAMENTO: | B5: =IFERROR(VLOOKUP($B$4,'Base TOTAL'!A:AJ,2,0), "Sin dato") -> Cruz del Eje
A6: TRAMITE PRE-OBRA
A7: Nº EXPEDIENTE 0135- : | B7: =IFERROR(VLOOKUP($B$4,'Base TOTAL'!A:AJ,3,0), "Sin dato") -> 0423-079111/2026
A8: MONTO TOTAL: | B8: =IFERROR(VLOOKUP($B$4,'Base TOTAL'!A:AJ,10,0), "Sin dato") -> 50000000
A9: ='Base TOTAL'!K3 -> Cordón Cuneta (ml) | B9: 440
A10: ='Base TOTAL'!L3 -> Adoquinado (m2) | B10: =IFERROR(VLOOKUP($B$4,'Base TOTAL'!A:AJ,12,0), "Sin dato")
A11: Estado de la documentación
A12: 1- Nota Solicitud de Financiamiento | B12: =IFERROR(VLOOKUP($B$4,'Base TOTAL'!A:AJ,13,0), "Sin dato") -> Sin Presentar
A13: 2- Ordenanza y Decreto/ Resolución comunal | B13: =IFERROR(VLOOKUP($B$4,'Base TOTAL'!A:AJ,14,0), "Sin dato") -> Sin Presentar
A14: 3- DDJJ compromiso de ejecuciòn obra | B14: =IFERROR(VLOOKUP($B$4,'Base TOTAL'!A:AJ,15,0), "Sin dato") -> Sin Presentar
A15: 4- Proyecto, Planos, Còmputo y Presupuesto | B15: =IFERROR(VLOOKUP($B$4,'Base TOTAL'!A:AJ,16,0), "Sin dato") -> A corregir por M/C
A16: Descripción General | B16: =IFERROR(VLOOKUP($B$4,'Base TOTAL'!A:AJ,17,0), "Sin dato") -> A corregir por M/C
A17: Memoria Técnica | B17: =IFERROR(VLOOKUP($B$4,'Base TOTAL'!A:AJ,18,0), "Sin dato") -> A corregir por M/C
A18: Plazo de Ejecución | B18: =IFERROR(VLOOKUP($B$4,'Base TOTAL'!A:AJ,19,0), "Sin dato") -> A corregir por M/C
A19: Cómputo y Presupuesto | B19: =IFERROR(VLOOKUP($B$4,'Base TOTAL'!A:AJ,20,0), "Sin dato") -> A corregir por M/C
A20: Cronograma Avance Obra | B20: =IFERROR(VLOOKUP($B$4,'Base TOTAL'!A:AJ,21,0), "Sin dato") -> A corregir por M/C
A21: Planimetría | B21: =IFERROR(VLOOKUP($B$4,'Base TOTAL'!A:AJ,22,0), "Sin dato") -> A corregir por M/C
A22: Perfil Calzada | B22: =IFERROR(VLOOKUP($B$4,'Base TOTAL'!A:AJ,23,0), "Sin dato") -> A corregir por M/C
A23: Detalle de Cordón Cuneta | B23: =IFERROR(VLOOKUP($B$4,'Base TOTAL'!A:AJ,24,0), "Sin dato") -> A corregir por M/C
A24: Detalle de Badén | B24: =IFERROR(VLOOKUP($B$4,'Base TOTAL'!A:AJ,25,0), "Sin dato") -> A corregir por M/C
A25: Paquete estr. Calzada | B25: =IFERROR(VLOOKUP($B$4,'Base TOTAL'!A:AJ,26,0), "Sin dato") -> A corregir por M/C
A26: 5- Nota a Contaduría Cesiòn Coparticipaciòn | B26: =IFERROR(VLOOKUP($B$4,'Base TOTAL'!A:AJ,27,0), "Sin dato") -> Sin Presentar
A27: 6- Nº CBU de M/C especial para depòsito de fondos | B27: =IFERROR(VLOOKUP($B$4,'Base TOTAL'!A:AJ,28,0), "Sin dato") -> Sin Presentar
A28: 7- Nº CUIT Municipal / Comunal | B28: =IFERROR(VLOOKUP($B$4,'Base TOTAL'!A:AJ,29,0), "Sin dato") -> Sin Presentar
A29: 8- DNI Intendente / Jefe Comunal | B29: =IFERROR(VLOOKUP($B$4,'Base TOTAL'!A:AJ,30,0), "Sin dato") -> Sin Presentar
A30: 9- Acta de Proclamación Int./Pres. Com. | B30: =IFERROR(VLOOKUP($B$4,'Base TOTAL'!A:AJ,31,0), "Sin dato") -> Sin Presentar
A32: ='Base TOTAL'!AG2 -> OBSERVACIONES
A33: =IFERROR(VLOOKUP($B$4,'Base TOTAL'!A:AJ,33,0), "Sin dato") -> 18/6/26: Se envìa Instructivo de documentaciòn legal y tècnica a presentar por M-C. EL 29/04/26 SE LE ENVÍA LOS REQUISITOS, VA A ENVIAR DOCUMENTACIÓN Completó el punto 4. Se le envió el 29/04/26 los restantes items para completar Expte.
A35: EXPEDIENTE RADICADO EN:
A36: ='Base TOTAL'!AH3 -> FECHA | B36: ='Base TOTAL'!AI3 -> REPARTICIÓN
A37: =IFERROR(VLOOKUP($B$4,'Base TOTAL'!A:AJ,34,0), "Sin dato") -> 46139 | B37: =IFERROR(VLOOKUP($B$4,'Base TOTAL'!A:AJ,35,0), "Sin dato") -> Técnica DGV

Sheet REP estado expediente
A1: OBRA: "EJECUCIÒN DE CORDÒN CUNETA Y ADOQUINADO"
A2: PROGRAMA: "PROVINCIAL DE CORDÒN CUNETA Y ADOQUINES" - LEY Nº 11.089
A3: REPORTE | B3: =TODAY() -> 46216
A4: ='Base TOTAL'!AF3 -> ESTADO DEL EXPEDIENTE DE LA LOCALIDAD | C4: COMPLETO en DGV
C5: =COUNTA(C7:C402) -> 396 | D5: ='Base TOTAL'!AH2 -> EXPEDIENTE RADICADO EN:
A6: Localidad | B6: Departamento | D6: ='Base TOTAL'!AH3 -> FECHA | E6: ='Base TOTAL'!AI3 -> REPARTICIÓN
A7: =IFERROR(__xludf.DUMMYFUNCTION("SORT(FILTER('Base TOTAL'!A:A, 'Base TOTAL'!AF:AF = C4))"),"Camilo Aldao") -> Camilo Aldao | B7: =IFERROR(VLOOKUP($A7,'Base TOTAL'!A:AJ,2,0), "-") -> Marcos Juárez | C7: =IFERROR(VLOOKUP($A7,'Base TOTAL'!A:AJ,33,0), "-") -> 13-07-2026 Se recibio doc. completa ordenada en 3 PDF 13-07-2026 Avisa la arqta. Gise, que enviò toda la doc. por mail. NO llego, se dio aviso para su re envio 08-07-2026 Se solicita al arq. la Present. de toda la doc. corregida completa s/ intructivo (Como iniciar el tram.) 07-07-2026 Se recibe doc. para completar pto 9 03/7/2026: Se solicita completen el acta de aceptación del cargo del intendente. 30/6/2026: Expte. PASA A LEGALES 29/6/2026: Documentaciòn en orden para anexar al Expte. y dar curso. - 05-06-2026 - Pto. 4 ( Falta cronograma de avance de obra + En planimetria gral. colocar las Geo referencias de los cuatro sectores de obra) Se solicitan nuevos cambios. COMPLETÓ DOCUMENTACIÓN 01/06/26 - Se pasan las actuaciones a arq. Carlos Viana para enviar a Jurídico Se envían el 26/05/26, nuevas correcciones, se recibe nueva documentación técnica el 29/05/26. 07-07-2026 Se recibe doc. Pto. 9 p/ completar exp. El 26/05/26 se envió correcciones a la parte técnica. Documentación Corregida. Sube a Jurídico El 19/05/26 se recibe documentación corregida para su análisis. El 11/5/26 se logra comunicación con municipalidad. Se pasa por whatsapp la documentación modelo. | D7: =IFERROR(VLOOKUP($A7,'Base TOTAL'!A:AJ,34,0), "-") -> 46205 | E7: =IFERROR(VLOOKUP($A7,'Base TOTAL'!A:AJ,35,0), "-") -> Jurídico DGV
A8: =IFERROR(__xludf.DUMMYFUNCTION("""COMPUTED_VALUE"""),"Colonia Italiana") -> Colonia Italiana | B8: =IFERROR(VLOOKUP($A8,'Base TOTAL'!A:AJ,2,0), "-") -> Marcos Juárez | C8: =IFERROR(VLOOKUP($A8,'Base TOTAL'!A:AJ,33,0), "-") -> 30/6/2026: Expte. PASA A LEGALES 29/6/2026: Documentaciòn en orden para anexar al Expte. y dar curso. 29/6/2026: Documentaciòn en orden para anexar al Expte. y dar curso. 19/6/26: Deben completar y corregir. 18/06/2026 enviaron memoria y doc tecnica corregida segun obervaciones. P- 17-06-2026 Se envìan correg/completar: ( firma y sello del prof. en cada hoja grafic.+ falta perfil transversal de calzada aunque no tenga paq. estr. determinando mat. de relleno) + pto.6 no se enviò imagen, del CBU el enviado tiene imagen parcial cortada) P- 11-06-2026 TEC.:( Faltan Memoria + Planim. con cotas + todos los detalles cortes + Cronogr. de Avances en 6 mese + todo sellado y firm x profes.) 11/6/26: Se solicita nuevamente la documentaciòn tècnica faltante. La arq. completará. P- 08-06-2026 - Pto. Nª 2 Falta Sello y firma del Tesorero o esta borroza Secr. tesor. + Pto. Nª 4 ( Faltan cotas grales de cada manz. en la planialtim. + cortes transv. + detalles + Planilla de avances cronograma de obra + Ubica y Memoria) El 30/04/26 vino la intendente Alejandra Ita a consultar por el Programa. Pregunta por el descuento por copa posterior. | D8: =IFERROR(VLOOKUP($A8,'Base TOTAL'!A:AJ,34,0), "-") -> 46205 | E8: =IFERROR(VLOOKUP($A8,'Base TOTAL'!A:AJ,35,0), "-") -> Jurídico DGV
A9: =IFERROR(__xludf.DUMMYFUNCTION("""COMPUTED_VALUE"""),"General Roca") -> General Roca | B9: =IFERROR(VLOOKUP($A9,'Base TOTAL'!A:AJ,2,0), "-") -> Marcos Juárez | C9: =IFERROR(VLOOKUP($A9,'Base TOTAL'!A:AJ,33,0), "-") -> Completó documentación y se elevó a jurídica para su estudio. COMPLETO. CON V°B° DE TÉCNICA. | D9: =IFERROR(VLOOKUP($A9,'Base TOTAL'!A:AJ,34,0), "-") -> 46205 | E9: =IFERROR(VLOOKUP($A9,'Base TOTAL'!A:AJ,35,0), "-") -> Tribunal de Cuentas
A10: =IFERROR(__xludf.DUMMYFUNCTION("""COMPUTED_VALUE"""),"La Paz") -> La Paz | B10: =IFERROR(VLOOKUP($A10,'Base TOTAL'!A:AJ,2,0), "-") -> San Javier | C10: =IFERROR(VLOOKUP($A10,'Base TOTAL'!A:AJ,33,0), "-") -> 08-07-2026 Se solicita al arq. la Present. de toda la doc. corregida completa s/ intructivo (Como iniciar el tram.) y Se resaltan completar detalles en esta present. ( Pto 2 que lleve ademas las firmas y sellos del tesorero e intend. + en Ptol 3 En la declar. Jurada si es el domic. real esquina sacar el S/N si no colocar las georef del mismo + en la Memoria Pto 3 plazo colocar s/ instruc. ) 30/6/2026: Expte. PASA A LEGALES 29/6/2026: Documentaciòn en orden para anexar al Expte. y dar curso. /// 23-06-2026 - Completo toda la doc. ( se recibe detalle de baden) 22-06-2026 - Solo falta detalle de baden se lo pedimos y le enviamos modelo al arq. Adrian RTA.: Enviado 19/6/26: Se solicita al arq. que presenta la documentaciòn a la mayor brevedad. 12-06-2026 -- Se solicita al arq. Adrian actualiz. correcc. -RTAS.: 11-06-2026 TEC.: ( solo falta det. baden ancho + paquete estruct. de calz + Geo ref. en Pl.gral) 04-06-2026 - Se tilda al Pto. Nª 4 (para que se modifique la unidad del cordon cun. a ml en el CM) EL 28/04/26 SE LE ENVÍA LOS REQUISITOS, VA A ENVIAR DOCUMENTACIÓN | D10: =IFERROR(VLOOKUP($A10,'Base TOTAL'!A:AJ,34,0), "-") -> 46205 | E10: =IFERROR(VLOOKUP($A10,'Base TOTAL'!A:AJ,35,0), "-") -> Jurídico DGV
A11: =IFERROR(__xludf.DUMMYFUNCTION("""COMPUTED_VALUE"""),"La Población") -> La Población | B11: =IFERROR(VLOOKUP($A11,'Base TOTAL'!A:AJ,2,0), "-") -> San Javier | C11: =IFERROR(VLOOKUP($A11,'Base TOTAL'!A:AJ,33,0), "-") -> 08-07-2026 Se solicita al arq. la Present. de toda la doc. corregida completa s/ intructivo (Como iniciar el tram.) 03-07-2026 Se reciben correcciones 03/7/2026: Se solicita al arq. corregir las observaciones (Faltan Georeferencias) 2026-07-01 Se solicito al arq. el complet. de geo ref en nota 3 y la firma del intend. en nota de ampliac. de doc. de georef. 2026-06-30 Se recibe modificacion parrafo Nota 5 solicitado al arq. --EXP. COMPLETO- 2026-06-30 Se recibe envio de Geo ref y se solicita modif. parrafo en nota 5 29/6/2026: Se reitera pedido de Geo-Ref. en Planim. Gral. 8/6/26 PASA DE AREA TECNICA A LEGALES // S-3-6-2026 Se observò desde Jurìdica falta en Punto Nª2 (son 3 firmas y falta..+ monto en la parte escrita) 3/6/2026 Se envió documentacion completa digital por email y lo recibiò Jurídica. COMPLETÓ documentación. Subió a Jurídico. Está en la Privada desde el 28/05/26 EL 20/05/26 SE APRUEBA LA PARTE TÉCNICA. SE SUBE A JURÍDICO PARA SU PROSECUCIÓN. EL 20/04/2026 LA COMUNA ENVÍA DOCUMENTACIÓN. FALTA INFO TÉCNICA. SE SOLICITA COMPLETAR LA MISMA. EL 14/04/26 SE CONTACTÓ AL PRESIDENTE COMUNAL - | D11: =IFERROR(VLOOKUP($A11,'Base TOTAL'!A:AJ,34,0), "-") -> 46199 | E11: =IFERROR(VLOOKUP($A11,'Base TOTAL'!A:AJ,35,0), "-") -> Técnica DGV
A12: =IFERROR(__xludf.DUMMYFUNCTION("""COMPUTED_VALUE"""),"Los Hornillos") -> Los Hornillos | B12: =IFERROR(VLOOKUP($A12,'Base TOTAL'!A:AJ,2,0), "-") -> San Javier | C12: =IFERROR(VLOOKUP($A12,'Base TOTAL'!A:AJ,33,0), "-") -> 8/6/26 PASA DE AREA TECNICA A LEGALES // P- 04-06-2026 - Se tilda al Pto. Nª 4 (para que se modifique la unidad del cordon cun. a ml en el Comp Metrico) EL 28/04/26 SE LE ENVÍA LOS REQUISITOS, VA A ENVIAR DOCUMENTACIÓNP- 3/6/2026 Se envió documentacion completa digital por email y lo recibiò Jurídica. EN CONDICIONES. EN LA PRIVADA DESDE 28/05/26 El 26/05/2026 se envía toda la Documentación completa con las correcciones ya corregidas por parte de la Comuna. El 26/5/26 se envía a Jurídico todo completo El 20/05/26 se aprueba la parte técnica, sube a jurídico. El 7/5/26 se envía escaneo de docum. Técnica para corregir, también se envía modelo de avance de obra por 6 meses. El 7/5/26 se solicitó corregir el punto 4 (doc. técnica) y se solicita cambio y corrección de Nota inicial. Presentó el 30/04/26 toda la documentación. El cómputo y presupuesto se pasa en $240.991-Se pide que se corrija. | D12: =IFERROR(VLOOKUP($A12,'Base TOTAL'!A:AJ,34,0), "-") -> 46199 | E12: =IFERROR(VLOOKUP($A12,'Base TOTAL'!A:AJ,35,0), "-") -> Tribunal de Cuentas
A13: =IFERROR(__xludf.DUMMYFUNCTION("""COMPUTED_VALUE"""),"San Javier y Yacanto") -> San Javier y Yacanto | B13: =IFERROR(VLOOKUP($A13,'Base TOTAL'!A:AJ,2,0), "-") -> San Javier | C13: =IFERROR(VLOOKUP($A13,'Base TOTAL'!A:AJ,33,0), "-") -> 03/7/2026: Se solicita al arq. y por Email municipio, corregir las observaciones (Faltan Georeferencias) 01-07-2026 - Se solicita al arq. Las Geo-Referenc. y la modicific. de la Nota Pto. 5 sacar ante ult. parrafo. 9/6/26 PASA DE AREA TECNICA A LEGALES. -04-06-2026 -(En Pto. 1 Nota Financ sacar la expres. vereda peinada y colocar tambien medida del cordòn en ml + en el Pto. 4 en el Comp. Metr. poner la medida del cordòn cunet. en ml) 3/6/2026 Se envió documentacion completa digital por email y fue recibida por Jurídica. COMPLETÓ documentación. Subió a Jurídico. Está en la Privada desde el 28/05/26 El 05/05/26 presentó la documentación, se exede en el montoasignado de $200.000.000 en $304.840 (se lo llama para que cambie) EL 16/04/26 VINO PERSONALMENTE EL INTENDENTE, MOSTRANDO INTERÉS. EL 14/04/26 SE CONTACTÓ AL INTENDENTE. | D13: =IFERROR(VLOOKUP($A13,'Base TOTAL'!A:AJ,34,0), "-") -> 46203 | E13: =IFERROR(VLOOKUP($A13,'Base TOTAL'!A:AJ,35,0), "-") -> Técnica DGV
A14: =IFERROR(__xludf.DUMMYFUNCTION("""COMPUTED_VALUE"""),"Tuclame") -> Tuclame | B14: =IFERROR(VLOOKUP($A14,'Base TOTAL'!A:AJ,2,0), "-") -> Cruz del Eje | C14: =IFERROR(VLOOKUP($A14,'Base TOTAL'!A:AJ,33,0), "-") -> COMPLETÓ documentación. Subió a Jurídico Con V°B°. EN LA PRIVADA DESDE 19/05/26 ENVIÓ LA DOCUMENTACIÓN. ESTÁS COMPLETA, SÓLO DEBE CORREGIR CRONOGRAMA DE INVERSIONES. COMPLETO. CON V°B° DE TÉCNICA | D14: =IFERROR(VLOOKUP($A14,'Base TOTAL'!A:AJ,34,0), "-") -> 46205 | E14: =IFERROR(VLOOKUP($A14,'Base TOTAL'!A:AJ,35,0), "-") -> Tribunal de Cuentas
A15: =IFERROR(__xludf.DUMMYFUNCTION("""COMPUTED_VALUE"""),"Villa Valeria") -> Villa Valeria | B15: =IFERROR(VLOOKUP($A15,'Base TOTAL'!A:AJ,2,0), "-") -> General Roca | C15: =IFERROR(VLOOKUP($A15,'Base TOTAL'!A:AJ,33,0), "-") -> 03/7/2026: PASO A LEGALES 10/6/2026 COMPLETÓ documentación. Subió a Jurídico Con V°B°. ARCHIVADO EL 13/05/26 El 12/5/26 se le envía "devolución" con correcciones de la documentación técnica presentada. COMPLETO. PASADO CON V°B° DE TÉCNICA. EL 30/04/26, EL INTENDENTE ENVÍA DOCUMENTACIÓN, QUE ESTÁ SIENDO ANALIZADA. DEBE COMPLETAR PUNTO 4, DE DOC. TÉCN. | D15: =IFERROR(VLOOKUP($A15,'Base TOTAL'!A:AJ,34,0), "-") -> 02/072026 | E15: =IFERROR(VLOOKUP($A15,'Base TOTAL'!A:AJ,35,0), "-") -> Tribunal de Cuentas
B16: =IFERROR(VLOOKUP($A16,'Base TOTAL'!A:AJ,2,0), "-") -> - | C16: =IFERROR(VLOOKUP($A16,'Base TOTAL'!A:AJ,33,0), "-") -> - | D16: =IFERROR(VLOOKUP($A16,'Base TOTAL'!A:AJ,34,0), "-") -> - | E16: =IFERROR(VLOOKUP($A16,'Base TOTAL'!A:AJ,35,0), "-") -> -
B17: =IFERROR(VLOOKUP($A17,'Base TOTAL'!A:AJ,2,0), "-") -> - | C17: =IFERROR(VLOOKUP($A17,'Base TOTAL'!A:AJ,33,0), "-") -> - | D17: =IFERROR(VLOOKUP($A17,'Base TOTAL'!A:AJ,34,0), "-") -> - | E17: =IFERROR(VLOOKUP($A17,'Base TOTAL'!A:AJ,35,0), "-") -> -
B18: =IFERROR(VLOOKUP($A18,'Base TOTAL'!A:AJ,2,0), "-") -> - | C18: =IFERROR(VLOOKUP($A18,'Base TOTAL'!A:AJ,33,0), "-") -> - | D18: =IFERROR(VLOOKUP($A18,'Base TOTAL'!A:AJ,34,0), "-") -> - | E18: =IFERROR(VLOOKUP($A18,'Base TOTAL'!A:AJ,35,0), "-") -> -
B19: =IFERROR(VLOOKUP($A19,'Base TOTAL'!A:AJ,2,0), "-") -> - | C19: =IFERROR(VLOOKUP($A19,'Base TOTAL'!A:AJ,33,0), "-") -> - | D19: =IFERROR(VLOOKUP($A19,'Base TOTAL'!A:AJ,34,0), "-") -> - | E19: =IFERROR(VLOOKUP($A19,'Base TOTAL'!A:AJ,35,0), "-") -> -
B20: =IFERROR(VLOOKUP($A20,'Base TOTAL'!A:AJ,2,0), "-") -> - | C20: =IFERROR(VLOOKUP($A20,'Base TOTAL'!A:AJ,33,0), "-") -> - | D20: =IFERROR(VLOOKUP($A20,'Base TOTAL'!A:AJ,34,0), "-") -> - | E20: =IFERROR(VLOOKUP($A20,'Base TOTAL'!A:AJ,35,0), "-") -> -
B21: =IFERROR(VLOOKUP($A21,'Base TOTAL'!A:AJ,2,0), "-") -> - | C21: =IFERROR(VLOOKUP($A21,'Base TOTAL'!A:AJ,33,0), "-") -> - | D21: =IFERROR(VLOOKUP($A21,'Base TOTAL'!A:AJ,34,0), "-") -> - | E21: =IFERROR(VLOOKUP($A21,'Base TOTAL'!A:AJ,35,0), "-") -> -
B22: =IFERROR(VLOOKUP($A22,'Base TOTAL'!A:AJ,2,0), "-") -> - | C22: =IFERROR(VLOOKUP($A22,'Base TOTAL'!A:AJ,33,0), "-") -> - | D22: =IFERROR(VLOOKUP($A22,'Base TOTAL'!A:AJ,34,0), "-") -> - | E22: =IFERROR(VLOOKUP($A22,'Base TOTAL'!A:AJ,35,0), "-") -> -
B23: =IFERROR(VLOOKUP($A23,'Base TOTAL'!A:AJ,2,0), "-") -> - | C23: =IFERROR(VLOOKUP($A23,'Base TOTAL'!A:AJ,33,0), "-") -> - | D23: =IFERROR(VLOOKUP($A23,'Base TOTAL'!A:AJ,34,0), "-") -> - | E23: =IFERROR(VLOOKUP($A23,'Base TOTAL'!A:AJ,35,0), "-") -> -
B24: =IFERROR(VLOOKUP($A24,'Base TOTAL'!A:AJ,2,0), "-") -> - | C24: =IFERROR(VLOOKUP($A24,'Base TOTAL'!A:AJ,33,0), "-") -> - | D24: =IFERROR(VLOOKUP($A24,'Base TOTAL'!A:AJ,34,0), "-") -> - | E24: =IFERROR(VLOOKUP($A24,'Base TOTAL'!A:AJ,35,0), "-") -> -
B25: =IFERROR(VLOOKUP($A25,'Base TOTAL'!A:AJ,2,0), "-") -> - | C25: =IFERROR(VLOOKUP($A25,'Base TOTAL'!A:AJ,33,0), "-") -> - | D25: =IFERROR(VLOOKUP($A25,'Base TOTAL'!A:AJ,34,0), "-") -> - | E25: =IFERROR(VLOOKUP($A25,'Base TOTAL'!A:AJ,35,0), "-") -> -
B26: =IFERROR(VLOOKUP($A26,'Base TOTAL'!A:AJ,2,0), "-") -> - | C26: =IFERROR(VLOOKUP($A26,'Base TOTAL'!A:AJ,33,0), "-") -> - | D26: =IFERROR(VLOOKUP($A26,'Base TOTAL'!A:AJ,34,0), "-") -> - | E26: =IFERROR(VLOOKUP($A26,'Base TOTAL'!A:AJ,35,0), "-") -> -
B27: =IFERROR(VLOOKUP($A27,'Base TOTAL'!A:AJ,2,0), "-") -> - | C27: =IFERROR(VLOOKUP($A27,'Base TOTAL'!A:AJ,33,0), "-") -> - | D27: =IFERROR(VLOOKUP($A27,'Base TOTAL'!A:AJ,34,0), "-") -> - | E27: =IFERROR(VLOOKUP($A27,'Base TOTAL'!A:AJ,35,0), "-") -> -
... B501: =IFERROR(VLOOKUP($A501,'Base TOTAL'!A:AJ,2,0), "-") -> - | C501: =IFERROR(VLOOKUP($A501,'Base TOTAL'!A:AJ,33,0), "-") -> - | D501: =IFERROR(VLOOKUP($A501,'Base TOTAL'!A:AJ,34,0), "-") -> - | E501: =IFERROR(VLOOKUP($A501,'Base TOTAL'!A:AJ,35,0), "-") -> -

Sheet Base TOTAL
A1: PROGRAMA PROVINCIAL DE CORDÓN CUNETA Y ADOQUINES - LEY Nº 11089 - AREA TECNICA - DIRECCIÓN GENERAL DE VIVENDA - MINISTERIO DE COOPERATIVAS Y MUTUALES - GOBIERNO DE CÒRDOBA
A2: LOCALIDAD / PROYECTO | B2: DEPARTAMENTO | C2: EXPEDIENTE N° | D2: N° Orden | E2: MUNICIPIO / COMUNA | F2: INTENDENTE / PRESIDENTE COMUNAL | G2: N° TELÉFONO M/C | H2: CORREO ELECTRÓNICO | I2: CONTACTO TÉCNICO de M/C | J2: CONVENIO | M2: DOCUMENTACIÓN A PRESENTAR por Municipio / Comuna | AG2: OBSERVACIONES | AH2: EXPEDIENTE RADICADO EN:
J3: MONTO CONVENIO | K3: Cordón Cuneta (ml) | L3: Adoquinado (m2) | M3: 1 | N3: 2 | O3: 3 | P3: 4 | Q3: Descripción General | R3: Memoria Técnica | S3: Plazo de Ejecución | T3: Cómputo y Presupuesto | U3: Cronograma Avance Obra | V3: Planimetría | W3: Perfil Calzada | X3: Detalle de Cordón Cuneta | Y3: Detalle de Badén | Z3: Paquete estr. Calzada | AA3: 5 | AB3: 6 | AC3: 7 | AD3: 8 | AE3: 9 | AF3: ESTADO DEL EXPEDIENTE DE LA LOCALIDAD | AH3: FECHA | AI3: REPARTICIÓN
A4: =COUNTA(A6:A55) -> 48 | J4: =SUM(J5:J56) -> 7065000000 | K4: =SUM(K5:K56) -> 8202.3 | L4: =SUM(L5:L56) -> 50710.12 | M4: =COUNTIF(M5:M56, "Completo OK") -> 14 | N4: =COUNTIF(N5:N56, "Completo OK") -> 17 | O4: =COUNTIF(O5:O56, "Completo OK") -> 15 | P4: =COUNTIF(P5:P56, "Completo OK") -> 13 | Q4: =COUNTIF(Q5:Q56, "Completo OK") -> 16 | R4: =COUNTIF(R5:R56, "Completo OK") -> 15 | S4: =COUNTIF(S5:S56, "Completo OK") -> 14 | T4: =COUNTIF(T5:T56, "Completo OK") -> 18 | ... AE4: =COUNTIF(AE5:AE56, "Completo OK") -> 16
A6: San Joaquín | B6: Presidente Roque Sáenz Peña | C6: 043-079116/2026 | D6: 1 | E6: C | F6: DANIEL PICCO | G6: (3385) 43-5407 | H6: Danielpicco66@hotmail.com | I6: laurirojas90@gmail.com | J6: 30000000 | K6: 206 | M6: A corregir por M/C | N6: En Evaluaciòn Jurìdico | O6: A corregir por M/C | P6: A corregir por M/C | Q6: Completo OK | R6: A corregir por M/C | S6: A corregir por M/C | T6: Completo OK | U6: Sin Presentar | V6: A corregir por M/C | W6: A corregir por M/C | X6: Completo OK | Y6: A corregir por M/C | Z6: Sin Presentar | AA6: A corregir por M/C | AB6: A corregir por M/C | AC6: En Evaluaciòn Jurìdico | AD6: En Evaluaciòn Jurìdico | AE6: En Evaluaciòn Jurìdico | AF6: En CURSO en DGV | AG6: 25/6/26: Comunicación con int. solicitando presenten correcciones. Se espera respuesta de la ing. a cargo. 19/6/26: Comunicaciòn con la ing. a cargo . Se solcita la presentaciòn a la mayor brevedad posible . 12-06-2026 Solicitar P Georef en Planim. + demas doc.Tec y leg 11/6/26: Se solicita nuevamente la correcciòn de Documentaciòn tècnica.Tiene todos los Items completos, salvo por el 4 (documentación técnica). El 29/5/26 se reclama la documentación firmada EL 19/05/26 PRESENTA PROYECTO CORREGIDO (A EVALUAR). EL 30/4 PRESENTAN NUEVO PRESUPUESTO, A VALOR $30.000.000. DEBE FUNDAMENTAR EL INCREMENTO EN EL MONTO TOTAL EL CÓMPUTO. El 30/04 se recibe y el monto que presenta es menor que el que se le da. Se pide que lo haga llegar al monto asignado El 28/04/26 se le envía documentación técnica modelo. EL 20/04/2026 LA COMUNA ENVÍA DOCUMENTACIÓN. FALTA INFO TÉCNICA. PRESENTA PRESUPUESTO, DE $21.969.370 - FALTA FIRMAS DE ÉSTE. EL 14/04/26 SE CONTACTÓ AL PRESIDENTE COMUNAL - | AH6: 46126 | AI6: Técnica DGV
A7: La Población | B7: San Javier | C7: 0423-079121/2026 | D7: 2 | E7: C | F7: EDUARDO ROMERO | G7: (3544) 58-0485 | H7: _ | I7: Arq. Adriàn Heredia (3544) 434500 Alejandra Castro (011) 6185-9307 | J7: 75000000 | K7: 440 | L7: 870 | M7: Completo OK | N7: Completo OK | O7: Completo OK | P7: Completo OK | Q7: Completo OK | R7: Completo OK | S7: Completo OK | T7: Completo OK | U7: Completo OK | V7: Completo OK | W7: Completo OK | X7: Completo OK | Y7: Completo OK | Z7: Completo OK | AA7: Completo OK | AB7: Completo OK | AC7: Completo OK | AD7: Completo OK | AE7: Completo OK | AF7: COMPLETO en DGV | AG7: 08-07-2026 Se solicita al arq. la Present. de toda la doc. corregida completa s/ intructivo (Como iniciar el tram.) 03-07-2026 Se reciben correcciones 03/7/2026: Se solicita al arq. corregir las observaciones (Faltan Georeferencias) 2026-07-01 Se solicito al arq. el complet. de geo ref en nota 3 y la firma del intend. en nota de ampliac. de doc. de georef. 2026-06-30 Se recibe modificacion parrafo Nota 5 solicitado al arq. --EXP. COMPLETO- 2026-06-30 Se recibe envio de Geo ref y se solicita modif. parrafo en nota 5 29/6/2026: Se reitera pedido de Geo-Ref. en Planim. Gral. 8/6/26 PASA DE AREA TECNICA A LEGALES // S-3-6-2026 Se observò desde Jurìdica falta en Punto Nª2 (son 3 firmas y falta..+ monto en la parte escrita) 3/6/2026 Se envió documentacion completa digital por email y lo recibiò Jurídica. COMPLETÓ documentación. Subió a Jurídico. Está en la Privada desde el 28/05/26 EL 20/05/26 SE APRUEBA LA PARTE TÉCNICA. SE SUBE A JURÍDICO PARA SU PROSECUCIÓN. EL 20/04/2026 LA COMUNA ENVÍA DOCUMENTACIÓN. FALTA INFO TÉCNICA. SE SOLICITA COMPLETAR LA MISMA. EL 14/04/26 SE CONTACTÓ AL PRESIDENTE COMUNAL - | AH7: 46199 | AI7: Técnica DGV
A8: Del Campillo | B8: General Roca | C8: 0423-079098/2026 | D8: 3 | E8: M | F8: CARLA VILLANOVA | G8: (3583) 40-1420 | H8: Carla.villanova480@gmail.com | J8: 200000000 | L8: 7440 | M8: En Evaluaciòn Jurìdico | N8: En Evaluaciòn Jurìdico | O8: En Evaluaciòn Jurìdico | P8: En Evaluaciòn Jurìdico | Q8: Completo OK | R8: Completo OK | S8: Completo OK | T8: Completo OK | U8: Completo OK | V8: A corregir por M/C | W8: Completo OK | X8: Sin Presentar | Y8: Sin Presentar | Z8: A corregir por M/C | AA8: En Evaluaciòn Jurìdico | AB8: En Evaluaciòn Jurìdico | AC8: En Evaluaciòn Jurìdico | AD8: En Evaluaciòn Jurìdico | AE8: En Evaluaciòn Jurìdico | AF8: En CURSO en DGV | AG8: - 22-06-2026 : Comunicaciòn con int. Se espera doc. tècnica y listo para dar continuidad al tràmite. - 19-06-2026 Se solicitan a la intend. Carla los siguientes: (Faltan en Planimetria Gral. las Geo ref. sobre las diferentes ubic. de obra + ampliar sobre la misma los nombres de las calles no se visualizan + corte paquete estr. de la calzada + detalles de baden s/ modelo) - 18-06-2026 Se envian al whats de intendenta y al mail los faltantes, correcciones y Modelo --RTAS.; Se recibe toda la doc. 4/6/2026 CB - VVVVVV 4/6/2026 HS - la documentacion tecnica tiene observaciones en el computo. esperaremos la vuelta desde jurídico. COMPLETÓ documentación. Subió a Jurídico Con V°B°. ARCHIVADO EL 13/05/26 EL 14/04/26 SE CONTACTÓ A LA INTENDENTE, LA CUAL ENVIÓ POSTERIORMENTE DOCUMENTACIÓN. SE SOLICITÓ EL COMPLETAMIENTO DE ITEM 4. COMPLETÓ PASADO CON V°B° TÉCNICA | AH8: 46155 | AI8: Jurídico DGV
A9: San Javier y Yacanto | B9: San Javier | C9: 0423-079118/2026 | D9: 4 | E9: M | F9: SEGUNDO MARTÍN GARCÍA | G9: (3544) 53-4283 | H9: garciam.s078@gmail.com | I9: Arq. Adriàn Heredia (3544) 434500 | J9: 200000000 | L9: 1823 | M9: Completo OK | N9: Completo OK | O9: A corregir por M/C | P9: Completo OK | Q9: Completo OK | R9: Completo OK | S9: Completo OK | T9: Completo OK | U9: Completo OK | V9: A corregir por M/C | W9: Completo OK | X9: Completo OK | Y9: Completo OK | Z9: Completo OK | AA9: Completo OK | AB9: Completo OK | AC9: Completo OK | AD9: Completo OK | AE9: Completo OK | AF9: COMPLETO en DGV | AG9: 03/7/2026: Se solicita al arq. y por Email municipio, corregir las observaciones (Faltan Georeferencias) 01-07-2026 - Se solicita al arq. Las Geo-Referenc. y la modicific. de la Nota Pto. 5 sacar ante ult. parrafo. 9/6/26 PASA DE AREA TECNICA A LEGALES. -04-06-2026 -(En Pto. 1 Nota Financ sacar la expres. vereda peinada y colocar tambien medida del cordòn en ml + en el Pto. 4 en el Comp. Metr. poner la medida del cordòn cunet. en ml) 3/6/2026 Se envió documentacion completa digital por email y fue recibida por Jurídica. COMPLETÓ documentación. Subió a Jurídico. Está en la Privada desde el 28/05/26 El 05/05/26 presentó la documentación, se exede en el montoasignado de $200.000.000 en $304.840 (se lo llama para que cambie) EL 16/04/26 VINO PERSONALMENTE EL INTENDENTE, MOSTRANDO INTERÉS. EL 14/04/26 SE CONTACTÓ AL INTENDENTE. | AH9: 46203 | AI9: Técnica DGV
A10: Cavanagh | B10: Marcos Juárez | C10: 0423-079101/2026 | D10: 55 | E10: M | F10: GUSTAVO DAL BO | G10: (3468) 64-7760 | H10: municavanagh@alejotv.com.ar | I10: richardquinn68@hotmail.com | J10: 300000000 | M10: A corregir por M/C | N10: A corregir por M/C | O10: A corregir por M/C | P10: A corregir por M/C | Q10: Sin Presentar | R10: Sin Presentar | S10: Sin Presentar | T10: Sin Presentar | U10: Sin Presentar | V10: Sin Presentar | W10: Sin Presentar | X10: Sin Presentar | Y10: Sin Presentar | Z10: Sin Presentar | AA10: Completo OK | AB10: Completo OK | AC10: Completo OK | AD10: Completo OK | AE10: Completo OK | AF10: En CURSO en DGV | AG10: 25-6-26: Comunicaciòn con Int. Solicita el Instructivo, se envìa. 10/6/2026: Se envìa doc. al arq. R. Quin para su correcc. x whatss P-10/6/2026: Se solicita al Municipio el contacto del ingeniero para enviar nuevamente lo que deben corregir P- 09-6-2026 Hablar con el intendente para avisar que este Progr. no contempla el asfaltado......-Pto. 1 -corregir nombre del Programa y plazo de ejecucion a 6 meses + Pto. 2 - No tiene el sello y firma de tesorero + Pto. 3 - corregir la denominaciòn del Programa + Pto. 7 el cuil presentado fue el del intend. No de la municipal. ? + 4/6/26:Presentan documentaciòn por Cidi- En evaluaciòn tècnica. EL 14/04/2026 SE CONTACTÓ AL INTENDENTE… QUEDÓ EN HABLAR, NO LO HIZOº | AH10: 46183 | AI10: Técnica DGV
A11: Capitán General Bernardo O'Higgins | B11: Marcos Juárez | C11: 0423-079103/2026 | D11: 6 | E11: M | F11: NORA BESSONE | G11: (3468) 56-1281 | H11: nora_bessone@hotmail.com | I11: muniohiggins@hotmail.com | J11: 200000000 | M11: A corregir por M/C | N11: Completo OK | O11: Completo OK | P11: Sin Presentar | Q11: A corregir por M/C | R11: A corregir por M/C | S11: A corregir por M/C | T11: A corregir por M/C | U11: Completo OK | V11: A corregir por M/C | W11: A corregir por M/C | X11: A corregir por M/C | Y11: A corregir por M/C | Z11: A corregir por M/C | AA11: Completo OK | AB11: Completo OK | AC11: Completo OK | AD11: Completo OK | AE11: Completo OK | AF11: En CURSO en DGV | AG11: 25-6-26: Comunicaciòn con int. y arq. para completen Georeferencia. 19/6/2026 se envian observaciones por email para corregir y completar. 18/6/26: Comunicación con el municipio para enviar Instructivo. EL 16/04/26 SE CONTACTÓ A LA INTENDENTE. EL 29/04/26 NOS VISITÓ Y CONSULTÓ. VA A ENVIAR DOCUMENTACIÓN | AH11: 46192 | AI11: Técnica DGV
A12: La Higuera | B12: Cruz del Eje | C12: 0423-079115/2026 | D12: 7 | E12: C | F12: DANIEL MANZANELLI | G12: (3542) 47-0003 | H12: Comunalahiguera01@gmail.com | I12: Ing. Bracamonte 3521401659 ---ingbracamontegustavo@gmail.com | J12: 100000000 | M12: A corregir por M/C | N12: A corregir por M/C | O12: A corregir por M/C | P12: A corregir por M/C | Q12: A corregir por M/C | R12: A corregir por M/C | S12: A corregir por M/C | T12: A corregir por M/C | U12: A corregir por M/C | V12: A corregir por M/C | W12: A corregir por M/C | X12: A corregir por M/C | Y12: A corregir por M/C | Z12: A corregir por M/C | AA12: Sin Presentar | AB12: Sin Presentar | AC12: Sin Presentar | AD12: Sin Presentar | AE12: Sin Presentar | AF12: En CURSO en DGV | AG12: 13-07-2026 Se llamo al ing. quien avisa que hoy envia doc. a la firma de la comuna y mañana nos envian por mail. 13/7/2026: Se solicita a la comuna y al ing. informen si puedieron avanzar con la documentaciòn. 13/7/2026: Se solicita a la comuna y al ing. informen si puedieron avanzar con la documentaciòn. 30-06-2026 Se reitera actualiz y completar docum. s/ instr. 26/6/2026: holaaaaaa 26/6/26: Se solicita al Ing. que complete la documentaciòn requerida conforme al Instructivo. 24/6/26: Se insiste y se hace un llamado al pres. comunal. Envìa datos por wathsapp. 22/6/26: Se solicita correo electrònico y datos del profesional para enviar instructivo. Sin respuesta 12-05-2026 Se envia las correcciones de la documentac. tecnica y la nota inial ( via whatsapp a Gonzalo Guzman El 30/04/2026 envían documentación de los items 1 a 5 para ver EL MARTES 28/04/26 SE HABLÓ POR TELÉFONO Y POR WHATSAPP, DONDE SE LE ENVIÓ LOS 9 PUNTOS Y SE COMPROMETIÓ EN DAR RESPUESTA. | AH12: 46139 | AI12: Técnica DGV
A13: Las Playas | B13: Cruz del Eje | C13: 0423-079112/2026 | D13: 8 | E13: C | F13: MARÍA DANIELA GODOY | G13: (3549) 46-8032 | H13: Danielagodoy79@gmail.com | I13: Ing. Bracamonte 3521401659 ---ingbracamontegustavo@gmail.com | J13: 200000000 | L13: 3922.22 | M13: A corregir por M/C | N13: Completo OK | O13: Completo OK | P13: A corregir por M/C | Q13: A corregir por M/C | R13: A corregir por M/C | S13: A corregir por M/C | T13: A corregir por M/C | U13: Sin Presentar | V13: A corregir por M/C | W13: A corregir por M/C | X13: Sin Presentar | Y13: Sin Presentar | Z13: A corregir por M/C | AA13: Completo OK | AB13: Completo OK | AC13: Completo OK | AD13: Completo OK | AE13: Completo OK | AF13: En CURSO en DGV | AG13: 13-7-2026: Se recibe de la intend. doc. por whast y se solicita que se envie en base a instructivo y por E mail. 13-7-2026: Se llamo al ing. quien avisa que el viernes enviò la doc. a la municip y mañana la envian firmada 13/7/2026: Se solicita informen còmo van con la documentaciòn a presentar. 29/6/2026: Se enviaron por Email las observaciones A corregir por la comuna 26/6/26: Se envían las observaciones a corregir por el ing. Se aguardan las observaciones del area Legales........22/6/26: El ing. se comunica con el àrea tècnica: Se le envìa el Instructivo de la documentaciòn legal y tècnica a presentar. 19/6/26: Sin respuesta del ing. a cargo, se envìa nuevamente el instructivo a la Pres. comunal. 11/6/26: Se solicita corregir documentación presentada. SE LE ENVIÓ LOS 9 REQUISITOS PARA PARTICIPAR EN EL PROGRAMA | AH13: 46139 | AI13: Técnica DGV
A14: Luyaba | B14: San Javier | C14: 0423-079120/2026 | D14: 9 | E14: C | F14: MAXIMILIANO PEREYRA | G14: (3544) 56-7381 | H14: Hectormaximilianopereyra@gmail.com | I14: Arq. Adriàn Heredia (3544) 434500 | J14: 150000000 | K14: 300 | L14: 2050 | M14: Completo OK | N14: Completo OK | O14: Completo OK | P14: Completo OK | Q14: Completo OK | R14: Completo OK | S14: Completo OK | T14: Completo OK | U14: Completo OK | V14: Completo OK | W14: Completo OK | X14: Completo OK | Y14: Completo OK | Z14: Completo OK | AA14: Completo OK | AB14: Completo OK | AC14: Completo OK | AD14: Completo OK | AE14: Completo OK | AF14: APROBADO por TC | AG14: 8/6/26 PASA DE AREA TECNICA A LEGALES // P -04-06-2026 -(En el Pto. 4 en el Comp. Metr. poner la medida del cordòn cunet. en ml) 3/6/2026 Se envió documentacion completa digital por email y lo recibiò Jurídica. 2/6/2026 corregido pasa a juridico El 27/05/2026 el municipio presentó el total de la información. APROBADA LA PARTE TÉCNICA. Debe corregir y presentar la Nota a Contaduría Gral y la DDJJ con firma clara 19/05/26 se aprueba la Parte Técnica. El 27/05/26 se recibe nueva documentación. 28/05/26 se pide que cambie nota a la contaduría y se le envía la nueva para que firme El 8/5/26 se le envió documentación modelo. Se recibió documenación de parte de la Comuna. La misma está en proceso de estudio y análisis. El | AH14: 46211 | AI14: Aprobado TC
