Workbook

Sheet IN x Localidad NATI
A1: Programas provinciales - Dirección General de Vivienda
A2: Ingreso de Datos
C3: LOCALIDAD: | D3: Sacanta | E3: ⬅️ solamente ELEGIR LOCALIDAD
C4: DEPARTAMENTO: | D4: =IFERROR(VLOOKUP($D$3,'Base TOTAL'!A:AU,2,0), "Sin dato") -> San Justo
C5: Datos actuales | D5: Modificar/Ingresar nuevo dato | E5: Columna ref. BASE TOTAL
B6: MUNICIPIO / COMUNA | C6: =LET(res, IFERROR(VLOOKUP($D$3,'Base TOTAL'!A:DA,5,0),""), IF(res="", "Sin datos", res)) -> M | D6: M | E6: E
B7: INTENDENTE / PRESIDENTE COMUNAL | C7: =LET(res, IFERROR(VLOOKUP($D$3,'Base TOTAL'!A:DA,6,0),""), IF(res="", "Sin datos", res)) -> Mecchia Jose Luis | E7: F
B8: N° TELÉFONO M/C | C8: =LET(res, IFERROR(VLOOKUP($D$3,'Base TOTAL'!A:DA,7,0),""), IF(res="", "Sin datos", res)) -> 3533580162 | E8: G
B9: CORREO ELECTRÓNICO | C9: =LET(res, IFERROR(VLOOKUP($D$3,'Base TOTAL'!A:DA,8,0),""), IF(res="", "Sin datos", res)) -> Secretariodegobierno@sacanta.gob.ar | E9: H
B10: CONTACTO TÉCNICO de M/C | C10: =LET(res, IFERROR(VLOOKUP($D$3,'Base TOTAL'!A:DA,9,0),""), IF(res="", "Sin datos", res)) -> jumagon82@gmail.com | E10: I
A11: PROGRAMA PROVINCIAL DE CORDÓN CUNETA Y ADOQUINES - LEY Nº 11089
B12: EXPEDIENTE N° | C12: =LET(res, IFERROR(VLOOKUP($D$3,'Base TOTAL'!A:DA,3,0),""), IF(res="", "Sin datos", res)) -> 0423-080124/2026 | E12: C
B13: N° Orden | C13: =LET(res, IFERROR(VLOOKUP($D$3,'Base TOTAL'!A:DA,4,0),""), IF(res="", "Sin datos", res)) -> 35 | E13: D
A14: CONVENIO | B14: MONTO CONVENIO | C14: =LET(res, IFERROR(VLOOKUP($D$3,'Base TOTAL'!A:DA,10,0),""), IF(res="", "Sin datos", res)) -> 70000000 | E14: J
B15: Cordón Cuneta (ml) | C15: =LET(res, IFERROR(VLOOKUP($D$3,'Base TOTAL'!A:DA,11,0),""), IF(res="", "Sin datos", res)) -> 1055 | E15: K
B16: Adoquinado (m2) | C16: =LET(res, IFERROR(VLOOKUP($D$3,'Base TOTAL'!A:DA,12,0),""), IF(res="", "Sin datos", res)) -> Sin datos | E16: L
A17: DOCUMENTACIÓN A PRESENTAR por Municipio / Comuna | B17: 1 | C17: =LET(res, IFERROR(VLOOKUP($D$3,'Base TOTAL'!A:DA,13,0),""), IF(res="", "Sin datos", res)) -> A corregir por M/C | E17: M
B18: 2 | C18: =LET(res, IFERROR(VLOOKUP($D$3,'Base TOTAL'!A:DA,14,0),""), IF(res="", "Sin datos", res)) -> Completo OK | E18: N
B19: 3 | C19: =LET(res, IFERROR(VLOOKUP($D$3,'Base TOTAL'!A:DA,15,0),""), IF(res="", "Sin datos", res)) -> Completo OK | E19: O
B20: 4 | C20: =LET(res, IFERROR(VLOOKUP($D$3,'Base TOTAL'!A:DA,16,0),""), IF(res="", "Sin datos", res)) -> A corregir por M/C | E20: P
B21: Descripción General | C21: =LET(res, IFERROR(VLOOKUP($D$3,'Base TOTAL'!A:DA,17,0),""), IF(res="", "Sin datos", res)) -> A corregir por M/C | E21: Q
B22: Memoria Técnica | C22: =LET(res, IFERROR(VLOOKUP($D$3,'Base TOTAL'!A:DA,18,0),""), IF(res="", "Sin datos", res)) -> Completo OK | E22: R
B23: Plazo de Ejecución | C23: =LET(res, IFERROR(VLOOKUP($D$3,'Base TOTAL'!A:DA,19,0),""), IF(res="", "Sin datos", res)) -> Completo OK | E23: S
B24: Cómputo y Presupuesto | C24: =LET(res, IFERROR(VLOOKUP($D$3,'Base TOTAL'!A:DA,20,0),""), IF(res="", "Sin datos", res)) -> A corregir por M/C | E24: T
B25: Cronograma Avance Obra | C25: =LET(res, IFERROR(VLOOKUP($D$3,'Base TOTAL'!A:DA,21,0),""), IF(res="", "Sin datos", res)) -> A corregir por M/C | E25: U
B26: Planimetría | C26: =LET(res, IFERROR(VLOOKUP($D$3,'Base TOTAL'!A:DA,22,0),""), IF(res="", "Sin datos", res)) -> Completo OK | E26: V
B27: Perfil Calzada | C27: =LET(res, IFERROR(VLOOKUP($D$3,'Base TOTAL'!A:DA,23,0),""), IF(res="", "Sin datos", res)) -> Completo OK | E27: W
B28: Detalle de Cordón Cuneta | C28: =LET(res, IFERROR(VLOOKUP($D$3,'Base TOTAL'!A:DA,24,0),""), IF(res="", "Sin datos", res)) -> Completo OK | E28: X
B29: Detalle de Badén | C29: =LET(res, IFERROR(VLOOKUP($D$3,'Base TOTAL'!A:DA,25,0),""), IF(res="", "Sin datos", res)) -> Completo OK | E29: Y
B30: Paquete estr. Calzada | C30: =LET(res, IFERROR(VLOOKUP($D$3,'Base TOTAL'!A:DA,26,0),""), IF(res="", "Sin datos", res)) -> A ESPERA de DOC.TÉCNICA | E30: Z
B31: 5 | C31: =LET(res, IFERROR(VLOOKUP($D$3,'Base TOTAL'!A:DA,27,0),""), IF(res="", "Sin datos", res)) -> Completo OK | E31: AA
B32: 6 | C32: =LET(res, IFERROR(VLOOKUP($D$3,'Base TOTAL'!A:DA,28,0),""), IF(res="", "Sin datos", res)) -> Completo OK | E32: AB
B33: 7 | C33: =LET(res, IFERROR(VLOOKUP($D$3,'Base TOTAL'!A:DA,29,0),""), IF(res="", "Sin datos", res)) -> Completo OK | E33: AC
B34: 8 | C34: =LET(res, IFERROR(VLOOKUP($D$3,'Base TOTAL'!A:DA,30,0),""), IF(res="", "Sin datos", res)) -> Completo OK | E34: AD
B35: 9 | C35: =LET(res, IFERROR(VLOOKUP($D$3,'Base TOTAL'!A:DA,31,0),""), IF(res="", "Sin datos", res)) -> Completo OK | E35: AE
B36: ESTADO DEL EXPEDIENTE DE LA LOCALIDAD | C36: =LET(res, IFERROR(VLOOKUP($D$3,'Base TOTAL'!A:DA,32,0),""), IF(res="", "Sin datos", res)) -> En CURSO en TÉCNICA | E36: AF
A37: OBSERVACIONES | C37: =LET(res, IFERROR(VLOOKUP($D$3,'Base TOTAL'!A:DA,33,0),""), IF(res="", "Sin datos", res)) -> 04/9/2026: Se envìan al arq. encargado las Observaciones A corregir. 20/8/2026: Se envìan por Email las Observaciones A corregir por el Munic. 03/8/2026: Se envìan correcc a intend. Secr tec e Infraestr. 29/6/2026: Se envía nuevamente al municipio (Email) el Instructivo de la documentación legal y técnica requerida. 24/6/26: El Intendente informa que el monto autorizado es de $100 mill. y no $70 como dice la autorización previa. Ya hizo la gestión para que corrijan. /// Se envía Instructivo de la documentación legal y técnica a presentar.....23/6/26: Comunicaciòn con municipio solicitando Correo electrònico. 5/6/26: Ingresa Nota Ministerio Gobierno autorizando financiamiento. | E37: AG
A38: EXPEDIENTE RADICADO EN: | B38: FECHA | C38: =LET(res, IFERROR(VLOOKUP($D$3,'Base TOTAL'!A:DA,34,0),""), IF(res="", "Sin datos", res)) -> 46178 | E38: AH
B39: REPARTICIÓN | C39: =LET(res, IFERROR(VLOOKUP($D$3,'Base TOTAL'!A:DA,35,0),""), IF(res="", "Sin datos", res)) -> DIRECCION DE JURISDICCION DE REGULARIZACION DE OBRAS Y PROYECTOS | E39: AI
B40: OBRA (En Ejecución)
...

Sheet IN x Localidad PABLO
A1: Programas provinciales - Dirección General de Vivienda
A2: Ingreso de Datos
C3: LOCALIDAD: | D3: El Arañado | E3: ⬅️ solamente ELEGIR LOCALIDAD
C4: DEPARTAMENTO: | D4: =IFERROR(VLOOKUP($D$3,'Base TOTAL'!A:AU,2,0), "Sin da") -> San Justo
C5: Datos actuales | D5: Modificar/Ingresar nuevo dato | E5: Columna ref. BASE TOTAL
B6: MUNICIPIO / COMUNA | C6: =LET(res, IFERROR(VLOOKUP($D$3,'Base TOTAL'!A:DA,5,0),""), IF(res="", "Sin datos", res)) -> Sin datos | E6: E
B7: INTENDENTE / PRESIDENTE COMUNAL | C7: =LET(res, IFERROR(VLOOKUP($D$3,'Base TOTAL'!A:DA,6,0),""), IF(res="", "Sin datos", res)) -> Gudiño Jorge Alino | E7: F
B8: N° TELÉFONO M/C | C8: =LET(res, IFERROR(VLOOKUP($D$3,'Base TOTAL'!A:DA,7,0),""), IF(res="", "Sin datos", res)) -> 3533442747 | E8: G
B9: CORREO ELECTRÓNICO | C9: =LET(res, IFERROR(VLOOKUP($D$3,'Base TOTAL'!A:DA,8,0),""), IF(res="", "Sin datos", res)) -> Jorgegudino276@gmail.com | E9: H
B10: CONTACTO TÉCNICO de M/C | C10: =LET(res, IFERROR(VLOOKUP($D$3,'Base TOTAL'!A:DA,9,0),""), IF(res="", "Sin datos", res)) -> ab.alcantaro@gmail.com | E10: I
A11: PROGRAMA PROVINCIAL DE CORDÓN CUNETA Y ADOQUINES - LEY Nº 11089
B12: EXPEDIENTE N° | C12: =LET(res, IFERROR(VLOOKUP($D$3,'Base TOTAL'!A:DA,3,0),""), IF(res="", "Sin datos", res)) -> 0423-080121/2026 | E12: C
B13: N° Orden | C13: =LET(res, IFERROR(VLOOKUP($D$3,'Base TOTAL'!A:DA,4,0),""), IF(res="", "Sin datos", res)) -> 45 | E13: D
A14: CONVENIO | B14: MONTO CONVENIO | C14: =LET(res, IFERROR(VLOOKUP($D$3,'Base TOTAL'!A:DA,10,0),""), IF(res="", "Sin datos", res)) -> 200000000 | E14: J
B15: Cordón Cuneta (ml) | C15: =LET(res, IFERROR(VLOOKUP($D$3,'Base TOTAL'!A:DA,11,0),""), IF(res="", "Sin datos", res)) -> Sin datos | E15: K
B16: Adoquinado (m2) | C16: =LET(res, IFERROR(VLOOKUP($D$3,'Base TOTAL'!A:DA,12,0),""), IF(res="", "Sin datos", res)) -> Sin datos | E16: L
A17: DOCUMENTACIÓN A PRESENTAR por Municipio / Comuna | B17: 1 | C17: =LET(res, IFERROR(VLOOKUP($D$3,'Base TOTAL'!A:DA,13,0),""), IF(res="", "Sin datos", res)) -> A ESPERA de DOC.TÉCNICA | E17: M
B18: 2 | C18: =LET(res, IFERROR(VLOOKUP($D$3,'Base TOTAL'!A:DA,14,0),""), IF(res="", "Sin datos", res)) -> A ESPERA de DOC.TÉCNICA | E18: N
B19: 3 | C19: =LET(res, IFERROR(VLOOKUP($D$3,'Base TOTAL'!A:DA,15,0),""), IF(res="", "Sin datos", res)) -> A ESPERA de DOC.TÉCNICA | E19: O
B20: 4 | C20: =LET(res, IFERROR(VLOOKUP($D$3,'Base TOTAL'!A:DA,16,0),""), IF(res="", "Sin datos", res)) -> A corregir por M/C | E20: P
B21: Descripción General | C21: =LET(res, IFERROR(VLOOKUP($D$3,'Base TOTAL'!A:DA,17,0),""), IF(res="", "Sin datos", res)) -> A corregir por M/C | E21: Q
B22: Memoria Técnica | C22: =LET(res, IFERROR(VLOOKUP($D$3,'Base TOTAL'!A:DA,18,0),""), IF(res="", "Sin datos", res)) -> A corregir por M/C | E22: R
B23: Plazo de Ejecución | C23: =LET(res, IFERROR(VLOOKUP($D$3,'Base TOTAL'!A:DA,19,0),""), IF(res="", "Sin datos", res)) -> A corregir por M/C | E23: S
B24: Cómputo y Presupuesto | C24: =LET(res, IFERROR(VLOOKUP($D$3,'Base TOTAL'!A:DA,20,0),""), IF(res="", "Sin datos", res)) -> A corregir por M/C | E24: T
B25: Cronograma Avance Obra | C25: =LET(res, IFERROR(VLOOKUP($D$3,'Base TOTAL'!A:DA,21,0),""), IF(res="", "Sin datos", res)) -> A corregir por M/C | E25: U
B26: Planimetría | C26: =LET(res, IFERROR(VLOOKUP($D$3,'Base TOTAL'!A:DA,22,0),""), IF(res="", "Sin datos", res)) -> A corregir por M/C | E26: V
B27: Perfil Calzada | C27: =LET(res, IFERROR(VLOOKUP($D$3,'Base TOTAL'!A:DA,23,0),""), IF(res="", "Sin datos", res)) -> A corregir por M/C | E27: W
B28: Detalle de Cordón Cuneta | C28: =LET(res, IFERROR(VLOOKUP($D$3,'Base TOTAL'!A:DA,24,0),""), IF(res="", "Sin datos", res)) -> A corregir por M/C | E28: X
B29: Detalle de Badén | C29: =LET(res, IFERROR(VLOOKUP($D$3,'Base TOTAL'!A:DA,25,0),""), IF(res="", "Sin datos", res)) -> A corregir por M/C | E29: Y
B30: Paquete estr. Calzada | C30: =LET(res, IFERROR(VLOOKUP($D$3,'Base TOTAL'!A:DA,26,0),""), IF(res="", "Sin datos", res)) -> A ESPERA de DOC.TÉCNICA | E30: Z
B31: 5 | C31: =LET(res, IFERROR(VLOOKUP($D$3,'Base TOTAL'!A:DA,27,0),""), IF(res="", "Sin datos", res)) -> A ESPERA de DOC.TÉCNICA | E31: AA
B32: 6 | C32: =LET(res, IFERROR(VLOOKUP($D$3,'Base TOTAL'!A:DA,28,0),""), IF(res="", "Sin datos", res)) -> A ESPERA de DOC.TÉCNICA | E32: AB
B33: 7 | C33: =LET(res, IFERROR(VLOOKUP($D$3,'Base TOTAL'!A:DA,29,0),""), IF(res="", "Sin datos", res)) -> A ESPERA de DOC.TÉCNICA | E33: AC
B34: 8 | C34: =LET(res, IFERROR(VLOOKUP($D$3,'Base TOTAL'!A:DA,30,0),""), IF(res="", "Sin datos", res)) -> A ESPERA de DOC.TÉCNICA | E34: AD
B35: 9 | C35: =LET(res, IFERROR(VLOOKUP($D$3,'Base TOTAL'!A:DA,31,0),""), IF(res="", "Sin datos", res)) -> A ESPERA de DOC.TÉCNICA | E35: AE
B36: ESTADO DEL EXPEDIENTE DE LA LOCALIDAD | C36: =LET(res, IFERROR(VLOOKUP($D$3,'Base TOTAL'!A:DA,32,0),""), IF(res="", "Sin datos", res)) -> En CURSO en TÉCNICA | E36: AF
A37: OBSERVACIONES | C37: =LET(res, IFERROR(VLOOKUP($D$3,'Base TOTAL'!A:DA,33,0),""), IF(res="", "Sin datos", res)) -> 20/8/2026: Se envía por Email, el Instructivo con el cambio de denominación. (Hoy Secretaría) 05/8/2026: Comunicaciòn con M/C enviando correo electrònico. 24/6/26:Comunicación con el municipio. Se envía Instructivo de la documentación legal y técnica requerida. 5/6/26: Ingresa Nota Ministerio Gobierno autorizando financiamiento. | E37: AG
A38: EXPEDIENTE RADICADO EN: | B38: FECHA | C38: =LET(res, IFERROR(VLOOKUP($D$3,'Base TOTAL'!A:DA,34,0),""), IF(res="", "Sin datos", res)) -> 46178 | E38: AH
B39: REPARTICIÓN | C39: =LET(res, IFERROR(VLOOKUP($D$3,'Base TOTAL'!A:DA,35,0),""), IF(res="", "Sin datos", res)) -> DIRECCION DE JURISDICCION DE REGULARIZACION DE OBRAS Y PROYECTOS | E39: AI
B40: OBRA (En Ejecución)
...

Sheet IN x Localidad H
A1: Programas provinciales - Dirección General de Vivienda
A2: Ingreso de Datos
C3: LOCALIDAD: | D3: Tuclame | E3: ⬅️ solamente ELEGIR LOCALIDAD
C4: DEPARTAMENTO: | D4: =IFERROR(VLOOKUP($D$3,'Base TOTAL'!A:AU,2,0), "Sin dato") -> Cruz del Eje
C5: Datos actuales | D5: Modificar/Ingresar nuevo dato | E5: Columna ref. BASE TOTAL
B6: MUNICIPIO / COMUNA | C6: =LET(res, IFERROR(VLOOKUP($D$3,'Base TOTAL'!A:DA,5,0),""), IF(res="", "Sin datos", res)) -> C | E6: E
B7: INTENDENTE / PRESIDENTE COMUNAL | C7: =LET(res, IFERROR(VLOOKUP($D$3,'Base TOTAL'!A:DA,6,0),""), IF(res="", "Sin datos", res)) -> GRACIELA DEL VALLE GONZÁLEZ | E7: F
B8: N° TELÉFONO M/C | C8: =LET(res, IFERROR(VLOOKUP($D$3,'Base TOTAL'!A:DA,7,0),""), IF(res="", "Sin datos", res)) -> (3549) 53-7628 | E8: G
B9: CORREO ELECTRÓNICO | C9: =LET(res, IFERROR(VLOOKUP($D$3,'Base TOTAL'!A:DA,8,0),""), IF(res="", "Sin datos", res)) -> gracieladelvallegonzalez20@gmail.com | E9: H
B10: CONTACTO TÉCNICO de M/C | C10: =LET(res, IFERROR(VLOOKUP($D$3,'Base TOTAL'!A:DA,9,0),""), IF(res="", "Sin datos", res)) -> ingbracamontegustavo@gmail.com | E10: I
A11: PROGRAMA PROVINCIAL DE CORDÓN CUNETA Y ADOQUINES - LEY Nº 11089
B12: EXPEDIENTE N° | C12: =LET(res, IFERROR(VLOOKUP($D$3,'Base TOTAL'!A:DA,3,0),""), IF(res="", "Sin datos", res)) -> 0423-079113/2026 | E12: C
B13: N° Orden | C13: =LET(res, IFERROR(VLOOKUP($D$3,'Base TOTAL'!A:DA,4,0),""), IF(res="", "Sin datos", res)) -> 16 | E13: D
A14: CONVENIO | B14: MONTO CONVENIO | C14: =LET(res, IFERROR(VLOOKUP($D$3,'Base TOTAL'!A:DA,10,0),""), IF(res="", "Sin datos", res)) -> 200000000 | E14: J
B15: Cordón Cuneta (ml) | C15: =LET(res, IFERROR(VLOOKUP($D$3,'Base TOTAL'!A:DA,11,0),""), IF(res="", "Sin datos", res)) -> 400 | E15: K
B16: Adoquinado (m2) | C16: =LET(res, IFERROR(VLOOKUP($D$3,'Base TOTAL'!A:DA,12,0),""), IF(res="", "Sin datos", res)) -> Sin datos | E16: L
A17: DOCUMENTACIÓN A PRESENTAR por Municipio / Comuna | B17: 1 | C17: =LET(res, IFERROR(VLOOKUP($D$3,'Base TOTAL'!A:DA,13,0),""), IF(res="", "Sin datos", res)) -> Completo OK | E17: M
B18: 2 | C18: =LET(res, IFERROR(VLOOKUP($D$3,'Base TOTAL'!A:DA,14,0),""), IF(res="", "Sin datos", res)) -> Completo OK | E18: N
B19: 3 | C19: =LET(res, IFERROR(VLOOKUP($D$3,'Base TOTAL'!A:DA,15,0),""), IF(res="", "Sin datos", res)) -> Completo OK | E19: O
B20: 4 | C20: =LET(res, IFERROR(VLOOKUP($D$3,'Base TOTAL'!A:DA,16,0),""), IF(res="", "Sin datos", res)) -> Completo OK | E20: P
B21: Descripción General | C21: =LET(res, IFERROR(VLOOKUP($D$3,'Base TOTAL'!A:DA,17,0),""), IF(res="", "Sin datos", res)) -> Completo OK | E21: Q
B22: Memoria Técnica | C22: =LET(res, IFERROR(VLOOKUP($D$3,'Base TOTAL'!A:DA,18,0),""), IF(res="", "Sin datos", res)) -> Completo OK | E22: R
B23: Plazo de Ejecución | C23: =LET(res, IFERROR(VLOOKUP($D$3,'Base TOTAL'!A:DA,19,0),""), IF(res="", "Sin datos", res)) -> Completo OK | E23: S
B24: Cómputo y Presupuesto | C24: =LET(res, IFERROR(VLOOKUP($D$3,'Base TOTAL'!A:DA,20,0),""), IF(res="", "Sin datos", res)) -> Completo OK | E24: T
B25: Cronograma Avance Obra | C25: =LET(res, IFERROR(VLOOKUP($D$3,'Base TOTAL'!A:DA,21,0),""), IF(res="", "Sin datos", res)) -> Completo OK | E25: U
B26: Planimetría | C26: =LET(res, IFERROR(VLOOKUP($D$3,'Base TOTAL'!A:DA,22,0),""), IF(res="", "Sin datos", res)) -> Completo OK | E26: V
B27: Perfil Calzada | C27: =LET(res, IFERROR(VLOOKUP($D$3,'Base TOTAL'!A:DA,23,0),""), IF(res="", "Sin datos", res)) -> Completo OK | E27: W
B28: Detalle de Cordón Cuneta | C28: =LET(res, IFERROR(VLOOKUP($D$3,'Base TOTAL'!A:DA,24,0),""), IF(res="", "Sin datos", res)) -> Completo OK | E28: X
B29: Detalle de Badén | C29: =LET(res, IFERROR(VLOOKUP($D$3,'Base TOTAL'!A:DA,25,0),""), IF(res="", "Sin datos", res)) -> Completo OK | E29: Y
B30: Paquete estr. Calzada | C30: =LET(res, IFERROR(VLOOKUP($D$3,'Base TOTAL'!A:DA,26,0),""), IF(res="", "Sin datos", res)) -> Completo OK | E30: Z
B31: 5 | C31: =LET(res, IFERROR(VLOOKUP($D$3,'Base TOTAL'!A:DA,27,0),""), IF(res="", "Sin datos", res)) -> Completo OK | E31: AA
B32: 6 | C32: =LET(res, IFERROR(VLOOKUP($D$3,'Base TOTAL'!A:DA,28,0),""), IF(res="", "Sin datos", res)) -> Completo OK | E32: AB
B33: 7 | C33: =LET(res, IFERROR(VLOOKUP($D$3,'Base TOTAL'!A:DA,29,0),""), IF(res="", "Sin datos", res)) -> Completo OK | E33: AC
B34: 8 | C34: =LET(res, IFERROR(VLOOKUP($D$3,'Base TOTAL'!A:DA,30,0),""), IF(res="", "Sin datos", res)) -> Completo OK | E34: AD
B35: 9 | C35: =LET(res, IFERROR(VLOOKUP($D$3,'Base TOTAL'!A:DA,31,0),""), IF(res="", "Sin datos", res)) -> Completo OK | E35: AE
B36: ESTADO DEL EXPEDIENTE DE LA LOCALIDAD | C36: =LET(res, IFERROR(VLOOKUP($D$3,'Base TOTAL'!A:DA,32,0),""), IF(res="", "Sin datos", res)) -> OBRA en EJECUCIÓN | E36: AF
A37: OBSERVACIONES | C37: =LET(res, IFERROR(VLOOKUP($D$3,'Base TOTAL'!A:DA,33,0),""), IF(res="", "Sin datos", res)) -> 07/8/2026: Se pagò A.F. el 5/8/2026 05/8/2026: PASA A EONOMICO-FINANCIERO para pago de A.F. 04/8/2026: Envìan Certif. y Nota a Silvia. 04/8/2026: Se envìa Modelo de Cert. A.F. A completar por la comuna y presentar. COMPLETÓ documentación. Subió a Jurídico Con V°B°. EN LA PRIVADA DESDE 19/05/26 ENVIÓ LA DOCUMENTACIÓN. ESTÁS COMPLETA, SÓLO DEBE CORREGIR CRONOGRAMA DE INVERSIONES. COMPLETO. CON V°B° DE TÉCNICA | E37: AG
A38: EXPEDIENTE RADICADO EN: | B38: FECHA | C38: =LET(res, IFERROR(VLOOKUP($D$3,'Base TOTAL'!A:DA,34,0),""), IF(res="", "Sin datos", res)) -> 46231 | E38: AH
B39: REPARTICIÓN | C39: =LET(res, IFERROR(VLOOKUP($D$3,'Base TOTAL'!A:DA,35,0),""), IF(res="", "Sin datos", res)) -> DIRECCION DE JURISDICCION ECONOMICO, FINANCIERA Y DE ADMINISTRACION | E39: AI
B40: OBRA (En Ejecución)
...

Sheet IN x Localidad BETINA
A1: Programas provinciales - Dirección General de Vivienda
A2: Ingreso de Datos
C3: LOCALIDAD: | D3: Del Campillo | E3: ⬅️ solamente ELEGIR LOCALIDAD
C4: DEPARTAMENTO: | D4: =IFERROR(VLOOKUP($D$3,'Base TOTAL'!A:AU,2,0), "Sin dato") -> General Roca
C5: Datos actuales | D5: Modificar/Ingresar nuevo dato | E5: Columna ref. BASE TOTAL
B6: MUNICIPIO / COMUNA | C6: =LET(res, IFERROR(VLOOKUP($D$3,'Base TOTAL'!A:DA,5,0),""), IF(res="", "Sin datos", res)) -> M | E6: E
B7: INTENDENTE / PRESIDENTE COMUNAL | C7: =LET(res, IFERROR(VLOOKUP($D$3,'Base TOTAL'!A:DA,6,0),""), IF(res="", "Sin datos", res)) -> CARLA VILLANOVA | E7: F
B8: N° TELÉFONO M/C | C8: =LET(res, IFERROR(VLOOKUP($D$3,'Base TOTAL'!A:DA,7,0),""), IF(res="", "Sin datos", res)) -> (3583) 40-1420 | E8: G
B9: CORREO ELECTRÓNICO | C9: =LET(res, IFERROR(VLOOKUP($D$3,'Base TOTAL'!A:DA,8,0),""), IF(res="", "Sin datos", res)) -> Carla.villanova480@gmail.com | E9: H
B10: CONTACTO TÉCNICO de M/C | C10: =LET(res, IFERROR(VLOOKUP($D$3,'Base TOTAL'!A:DA,9,0),""), IF(res="", "Sin datos", res)) -> Carlota.Bertorello@gmail.com | E10: I
A11: PROGRAMA PROVINCIAL DE CORDÓN CUNETA Y ADOQUINES - LEY Nº 11089
B12: EXPEDIENTE N° | C12: =LET(res, IFERROR(VLOOKUP($D$3,'Base TOTAL'!A:DA,3,0),""), IF(res="", "Sin datos", res)) -> 0423-079098/2026 | E12: C
B13: N° Orden | C13: =LET(res, IFERROR(VLOOKUP($D$3,'Base TOTAL'!A:DA,4,0),""), IF(res="", "Sin datos", res)) -> 3 | E13: D
A14: CONVENIO | B14: MONTO CONVENIO | C14: =LET(res, IFERROR(VLOOKUP($D$3,'Base TOTAL'!A:DA,10,0),""), IF(res="", "Sin datos", res)) -> 200000000 | E14: J
B15: Cordón Cuneta (ml) | C15: =LET(res, IFERROR(VLOOKUP($D$3,'Base TOTAL'!A:DA,11,0),""), IF(res="", "Sin datos", res)) -> Sin datos | E15: K
B16: Adoquinado (m2) | C16: =LET(res, IFERROR(VLOOKUP($D$3,'Base TOTAL'!A:DA,12,0),""), IF(res="", "Sin datos", res)) -> 7440 | E16: L
A17: DOCUMENTACIÓN A PRESENTAR por Municipio / Comuna | B17: 1 | C17: =LET(res, IFERROR(VLOOKUP($D$3,'Base TOTAL'!A:DA,13,0),""), IF(res="", "Sin datos", res)) -> Completo OK | E17: M
B18: 2 | C18: =LET(res, IFERROR(VLOOKUP($D$3,'Base TOTAL'!A:DA,14,0),""), IF(res="", "Sin datos", res)) -> Completo OK | E18: N
B19: 3 | C19: =LET(res, IFERROR(VLOOKUP($D$3,'Base TOTAL'!A:DA,15,0),""), IF(res="", "Sin datos", res)) -> Completo OK | E19: O
B20: 4 | C20: =LET(res, IFERROR(VLOOKUP($D$3,'Base TOTAL'!A:DA,16,0),""), IF(res="", "Sin datos", res)) -> Completo OK | E20: P
B21: Descripción General | C21: =LET(res, IFERROR(VLOOKUP($D$3,'Base TOTAL'!A:DA,17,0),""), IF(res="", "Sin datos", res)) -> Completo OK | E21: Q
B22: Memoria Técnica | C22: =LET(res, IFERROR(VLOOKUP($D$3,'Base TOTAL'!A:DA,18,0),""), IF(res="", "Sin datos", res)) -> Completo OK | E22: R
B23: Plazo de Ejecución | C23: =LET(res, IFERROR(VLOOKUP($D$3,'Base TOTAL'!A:DA,19,0),""), IF(res="", "Sin datos", res)) -> Completo OK | E23: S
B24: Cómputo y Presupuesto | C24: =LET(res, IFERROR(VLOOKUP($D$3,'Base TOTAL'!A:DA,20,0),""), IF(res="", "Sin datos", res)) -> Completo OK | E24: T
B25: Cronograma Avance Obra | C25: =LET(res, IFERROR(VLOOKUP($D$3,'Base TOTAL'!A:DA,21,0),""), IF(res="", "Sin datos", res)) -> Completo OK | E25: U
B26: Planimetría | C26: =LET(res, IFERROR(VLOOKUP($D$3,'Base TOTAL'!A:DA,22,0),""), IF(res="", "Sin datos", res)) -> Completo OK | E26: V
B27: Perfil Calzada | C27: =LET(res, IFERROR(VLOOKUP($D$3,'Base TOTAL'!A:DA,23,0),""), IF(res="", "Sin datos", res)) -> Completo OK | E27: W
B28: Detalle de Cordón Cuneta | C28: =LET(res, IFERROR(VLOOKUP($D$3,'Base TOTAL'!A:DA,24,0),""), IF(res="", "Sin datos", res)) -> A ESPERA de DOC.TÉCNICA | E28: X
B29: Detalle de Badén | C29: =LET(res, IFERROR(VLOOKUP($D$3,'Base TOTAL'!A:DA,25,0),""), IF(res="", "Sin datos", res)) -> A ESPERA de DOC.TÉCNICA | E29: Y
B30: Paquete estr. Calzada | C30: =LET(res, IFERROR(VLOOKUP($D$3,'Base TOTAL'!A:DA,26,0),""), IF(res="", "Sin datos", res)) -> Completo OK | E30: Z
B31: 5 | C31: =LET(res, IFERROR(VLOOKUP($D$3,'Base TOTAL'!A:DA,27,0),""), IF(res="", "Sin datos", res)) -> Completo OK | E31: AA
B32: 6 | C32: =LET(res, IFERROR(VLOOKUP($D$3,'Base TOTAL'!A:DA,28,0),""), IF(res="", "Sin datos", res)) -> Completo OK | E32: AB
B33: 7 | C33: =LET(res, IFERROR(VLOOKUP($D$3,'Base TOTAL'!A:DA,29,0),""), IF(res="", "Sin datos", res)) -> Completo OK | E33: AC
B34: 8 | C34: =LET(res, IFERROR(VLOOKUP($D$3,'Base TOTAL'!A:DA,30,0),""), IF(res="", "Sin datos", res)) -> Completo OK | E34: AD
B35: 9 | C35: =LET(res, IFERROR(VLOOKUP($D$3,'Base TOTAL'!A:DA,31,0),""), IF(res="", "Sin datos", res)) -> Completo OK | E35: AE
B36: ESTADO DEL EXPEDIENTE DE LA LOCALIDAD | C36: =LET(res, IFERROR(VLOOKUP($D$3,'Base TOTAL'!A:DA,32,0),""), IF(res="", "Sin datos", res)) -> COMPLETO en TÉCNICA | E36: AF
A37: OBSERVACIONES | C37: =LET(res, IFERROR(VLOOKUP($D$3,'Base TOTAL'!A:DA,33,0),""), IF(res="", "Sin datos", res)) -> 20/8/2026: PASA A LEGALES para prosecuciòn del tràmite. 11/8/2026: Se recibe doc. completa, avisa juridica que la doc. esta completa. Se envian al Email del prof. + intend. + infra. de las correcc. s/ la doc. presentada ayer 10/8/2026: Respuesta de arq: "Ya tengo todo hecho! Me falta armar los 3 pdf y pasarlosEstuve con mi bebé en Cba en el médico hasta ayer.. asique en lo que queda de la tarde no durante y el finde paso todo por mail" 30/7/2026: Se solicita a la arq. informe si pudieron avanzar con la documentaciòn. Respuesta: " estoy en Cba en el médico Asique hasta la semana que viene no voy a tener corregida la documentación /// Lunes o martes ya seguro que estoy pasando todo" 24/7/2026: Se envìa por Email las Observaciones A corregir por el municipio. 23/7/2026: La arq. envìa doc. tècnica en borrador para su evaluaciòn. 16/7/2026: Comunicaciòn con la arq. (Estuvo demorada por Maternidad) y dice que està preparando la documentaciòn para presentar. - 22-06-2026 : Comunicaciòn con int. Se espera doc. tècnica y listo para dar continuidad al tràmite. - 19-06-2026 Se solicitan a la intend. Carla los siguientes: (Faltan en Planimetria Gral. las Geo ref. sobre las diferentes ubic. de obra + ampliar sobre la misma los nombres de las calles no se visualizan + corte paquete estr. de la calzada + detalles de baden s/ modelo) - 18-06-2026 Se envian al whats de intendenta y al mail los faltantes, correcciones y Modelo --RTAS.; Se recibe toda la doc. 4/6/2026 CB - VVVVVV 4/6/2026 HS - la documentacion tecnica tiene observaciones en el computo. esperaremos la vuelta desde jurídico. COMPLETÓ documentación. Subió a Jurídico Con V°B°. ARCHIVADO EL 13/05/26 EL 14/04/26 SE CONTACTÓ A LA INTENDENTE, LA CUAL ENVIÓ POSTERIORMENTE DOCUMENTACIÓN. SE SOLICITÓ EL COMPLETAMIENTO DE ITEM 4. COMPLETÓ PASADO CON V°B° TÉCNICA | E37: AG
A38: EXPEDIENTE RADICADO EN: | B38: FECHA | C38: =LET(res, IFERROR(VLOOKUP($D$3,'Base TOTAL'!A:DA,34,0),""), IF(res="", "Sin datos", res)) -> 46227 | E38: AH
B39: REPARTICIÓN | C39: =LET(res, IFERROR(VLOOKUP($D$3,'Base TOTAL'!A:DA,35,0),""), IF(res="", "Sin datos", res)) -> AREA COORDINACION ADMINISTRATIVA | E39: AI
B40: OBRA (En Ejecución)
...

Sheet IN x Localidad GREGORAT
A1: Programas provinciales - Dirección General de Vivienda
A2: Ingreso de Datos
C3: LOCALIDAD: | D3: San Joaquín | E3: ⬅️ solamente ELEGIR LOCALIDAD
C4: DEPARTAMENTO: | D4: =IFERROR(VLOOKUP($D$3,'Base TOTAL'!A:AU,2,0), "Sin dato") -> Presidente Roque Sáenz Peña
C5: Datos actuales | D5: Modificar/Ingresar nuevo dato | E5: Columna ref. BASE TOTAL
B6: MUNICIPIO / COMUNA | C6: =LET(res, IFERROR(VLOOKUP($D$3,'Base TOTAL'!A:DA,5,0),""), IF(res="", "Sin datos", res)) -> C | E6: E
B7: INTENDENTE / PRESIDENTE COMUNAL | C7: =LET(res, IFERROR(VLOOKUP($D$3,'Base TOTAL'!A:DA,6,0),""), IF(res="", "Sin datos", res)) -> DANIEL PICCO | E7: F
B8: N° TELÉFONO M/C | C8: =LET(res, IFERROR(VLOOKUP($D$3,'Base TOTAL'!A:DA,7,0),""), IF(res="", "Sin datos", res)) -> (3385) 43-5407 | E8: G
B9: CORREO ELECTRÓNICO | C9: =LET(res, IFERROR(VLOOKUP($D$3,'Base TOTAL'!A:DA,8,0),""), IF(res="", "Sin datos", res)) -> Danielpicco66@hotmail.com | E9: H
B10: CONTACTO TÉCNICO de M/C | C10: =LET(res, IFERROR(VLOOKUP($D$3,'Base TOTAL'!A:DA,9,0),""), IF(res="", "Sin datos", res)) -> mafer76_4@hotmail.com | E10: I
A11: PROGRAMA PROVINCIAL DE CORDÓN CUNETA Y ADOQUINES - LEY Nº 11089
B12: EXPEDIENTE N° | C12: =LET(res, IFERROR(VLOOKUP($D$3,'Base TOTAL'!A:DA,3,0),""), IF(res="", "Sin datos", res)) -> 043-079116/2026 | E12: C
B13: N° Orden | C13: =LET(res, IFERROR(VLOOKUP($D$3,'Base TOTAL'!A:DA,4,0),""), IF(res="", "Sin datos", res)) -> 1 | E13: D
A14: CONVENIO | B14: MONTO CONVENIO | C14: =LET(res, IFERROR(VLOOKUP($D$3,'Base TOTAL'!A:DA,10,0),""), IF(res="", "Sin datos", res)) -> 30000000 | E14: J
B15: Cordón Cuneta (ml) | C15: =LET(res, IFERROR(VLOOKUP($D$3,'Base TOTAL'!A:DA,11,0),""), IF(res="", "Sin datos", res)) -> 206 | E15: K
B16: Adoquinado (m2) | C16: =LET(res, IFERROR(VLOOKUP($D$3,'Base TOTAL'!A:DA,12,0),""), IF(res="", "Sin datos", res)) -> Sin datos | E16: L
A17: DOCUMENTACIÓN A PRESENTAR por Municipio / Comuna | B17: 1 | C17: =LET(res, IFERROR(VLOOKUP($D$3,'Base TOTAL'!A:DA,13,0),""), IF(res="", "Sin datos", res)) -> Completo OK | E17: M
B18: 2 | C18: =LET(res, IFERROR(VLOOKUP($D$3,'Base TOTAL'!A:DA,14,0),""), IF(res="", "Sin datos", res)) -> Completo OK | E18: N
B19: 3 | C19: =LET(res, IFERROR(VLOOKUP($D$3,'Base TOTAL'!A:DA,15,0),""), IF(res="", "Sin datos", res)) -> Completo OK | E19: O
B20: 4 | C20: =LET(res, IFERROR(VLOOKUP($D$3,'Base TOTAL'!A:DA,16,0),""), IF(res="", "Sin datos", res)) -> Completo OK | E20: P
B21: Descripción General | C21: =LET(res, IFERROR(VLOOKUP($D$3,'Base TOTAL'!A:DA,17,0),""), IF(res="", "Sin datos", res)) -> Completo OK | E21: Q
B22: Memoria Técnica | C22: =LET(res, IFERROR(VLOOKUP($D$3,'Base TOTAL'!A:DA,18,0),""), IF(res="", "Sin datos", res)) -> Completo OK | E22: R
B23: Plazo de Ejecución | C23: =LET(res, IFERROR(VLOOKUP($D$3,'Base TOTAL'!A:DA,19,0),""), IF(res="", "Sin datos", res)) -> Completo OK | E23: S
B24: Cómputo y Presupuesto | C24: =LET(res, IFERROR(VLOOKUP($D$3,'Base TOTAL'!A:DA,20,0),""), IF(res="", "Sin datos", res)) -> Completo OK | E24: T
B25: Cronograma Avance Obra | C25: =LET(res, IFERROR(VLOOKUP($D$3,'Base TOTAL'!A:DA,21,0),""), IF(res="", "Sin datos", res)) -> Completo OK | E25: U
B26: Planimetría | C26: =LET(res, IFERROR(VLOOKUP($D$3,'Base TOTAL'!A:DA,22,0),""), IF(res="", "Sin datos", res)) -> Completo OK | E26: V
B27: Perfil Calzada | C27: =LET(res, IFERROR(VLOOKUP($D$3,'Base TOTAL'!A:DA,23,0),""), IF(res="", "Sin datos", res)) -> Completo OK | E27: W
B28: Detalle de Cordón Cuneta | C28: =LET(res, IFERROR(VLOOKUP($D$3,'Base TOTAL'!A:DA,24,0),""), IF(res="", "Sin datos", res)) -> Completo OK | E28: X
B29: Detalle de Badén | C29: =LET(res, IFERROR(VLOOKUP($D$3,'Base TOTAL'!A:DA,25,0),""), IF(res="", "Sin datos", res)) -> Completo OK | E29: Y
B30: Paquete estr. Calzada | C30: =LET(res, IFERROR(VLOOKUP($D$3,'Base TOTAL'!A:DA,26,0),""), IF(res="", "Sin datos", res)) -> Completo OK | E30: Z
B31: 5 | C31: =LET(res, IFERROR(VLOOKUP($D$3,'Base TOTAL'!A:DA,27,0),""), IF(res="", "Sin datos", res)) -> Completo OK | E31: AA
B32: 6 | C32: =LET(res, IFERROR(VLOOKUP($D$3,'Base TOTAL'!A:DA,28,0),""), IF(res="", "Sin datos", res)) -> Completo OK | E32: AB
B33: 7 | C33: =LET(res, IFERROR(VLOOKUP($D$3,'Base TOTAL'!A:DA,29,0),""), IF(res="", "Sin datos", res)) -> Completo OK | E33: AC
B34: 8 | C34: =LET(res, IFERROR(VLOOKUP($D$3,'Base TOTAL'!A:DA,30,0),""), IF(res="", "Sin datos", res)) -> Completo OK | E34: AD
B35: 9 | C35: =LET(res, IFERROR(VLOOKUP($D$3,'Base TOTAL'!A:DA,31,0),""), IF(res="", "Sin datos", res)) -> DIR. JUR. LEGAL Y NOTARIAL | E35: AE
B36: ESTADO DEL EXPEDIENTE DE LA LOCALIDAD | C36: =LET(res, IFERROR(VLOOKUP($D$3,'Base TOTAL'!A:DA,32,0),""), IF(res="", "Sin datos", res)) -> En CURSO en TÉCNICA | E36: AF
A37: OBSERVACIONES | C37: =LET(res, IFERROR(VLOOKUP($D$3,'Base TOTAL'!A:DA,33,0),""), IF(res="", "Sin datos", res)) -> 28/8/2026: Se reciben actualizac. 21/8/2026: Se re-envian por whatss las Observac. a correg a la nva profes. 21/08/2026: Se reciben actualiz. x el Presid. Comunal x whatss del A.Legal y se confecciona la planilla de Observ. para anexar cuando la nva prof. envie actualiz. Tecnicas. 20/8/2026: Se envìa mensaje al Int. preguntando si pudieron corregir las Observaciones para presentar la documentaciòn. 29/7/2026: Se envìa Planilla de Observ. a corregir por la comuna , al nvo profesional y a Infraestr. 28/7/2026: El municipio cambiò de profesional. Se le envìa el instructivo a la nueva arq. 22/7/2026: Se envìa nuevamente al Email las observaciones A corregir por la comuna 22/7/2026: El 14/7/2026 presentan documentaciòn a corregir nuevamente. 25/6/26: Comunicación con int. solicitando presenten correcciones. Se espera respuesta de la ing. a cargo. 19/6/26: Comunicaciòn con la ing. a cargo . Se solcita la presentaciòn a la mayor brevedad posible . 12-06-2026 Solicitar P Georef en Planim. + demas doc.Tec y leg 11/6/26: Se solicita nuevamente la correcciòn de Documentaciòn tècnica.Tiene todos los Items completos, salvo por el 4 (documentación técnica). El 29/5/26 se reclama la documentación firmada EL 19/05/26 PRESENTA PROYECTO CORREGIDO (A EVALUAR). EL 30/4 PRESENTAN NUEVO PRESUPUESTO, A VALOR $30.000.000. DEBE FUNDAMENTAR EL INCREMENTO EN EL MONTO TOTAL EL CÓMPUTO. El 30/04 se recibe y el monto que presenta es menor que el que se le da. Se pide que lo haga llegar al monto asignado El 28/04/26 se le envía documentación técnica modelo. EL 20/04/2026 LA COMUNA ENVÍA DOCUMENTACIÓN. FALTA INFO TÉCNICA. PRESENTA PRESUPUESTO, DE $21.969.370 - FALTA FIRMAS DE ÉSTE. EL 14/04/26 SE CONTACTÓ AL PRESIDENTE COMUNAL - | E37: AG
A38: EXPEDIENTE RADICADO EN: | B38: FECHA | C38: =LET(res, IFERROR(VLOOKUP($D$3,'Base TOTAL'!A:DA,34,0),""), IF(res="", "Sin datos", res)) -> 46199 | E38: AH
B39: REPARTICIÓN | C39: =LET(res, IFERROR(VLOOKUP($D$3,'Base TOTAL'!A:DA,35,0),""), IF(res="", "Sin datos", res)) -> DIRECCION DE JURISDICCION ECONOMICO, FINANCIERA Y DE ADMINISTRACION | E39: AI
B40: OBRA (En Ejecución)
...

Sheet REP CC estado exp.
A1: OBRA: "EJECUCIÒN DE CORDÒN CUNETA Y ADOQUINADO"
A2: PROGRAMA: "PROVINCIAL DE CORDÒN CUNETA Y ADOQUINES" - LEY Nº 11.089
A3: REPORTE | B3: =TODAY() -> 46269
A4: ='Base TOTAL'!AF2 -> ESTADO DEL EXPEDIENTE DE LA LOCALIDAD | C4: En CURSO en TÉCNICA
C5: =COUNTIF(C7:C400, "<>-") -> 12 | D5: ='Base TOTAL'!AH2 -> EXP en FECHA
A6: Localidad | B6: Departamento | C6: ='Base TOTAL'!AG2 -> OBSERVACIONES | D6: ='Base TOTAL'!AH2 -> EXP en FECHA | E6: ='Base TOTAL'!AI2 -> EXP en REPARTICIÓN
A7: =IFERROR(__xludf.DUMMYFUNCTION("SORT(FILTER('Base TOTAL'!A:A, 'Base TOTAL'!AF:AF = C4))"),"Calchín") -> Calchín | B7: =IFERROR(VLOOKUP($A7,'Base TOTAL'!A:AU,2,0), "-") -> Río Segundo | C7: =IFERROR(VLOOKUP($A7,'Base TOTAL'!A:AU,33,0), "-") -> 31/8/2026: EL INT. RESPONDE que ya tiene todo para firmar y enviarnos. 31/8/2026: Comunicaciòn telefònica con Int. Sin respuesta. Se envìa mensaje por wahtsapp. 14/8/2026: Se envìan Observac. p/ corregir por Email al munic. e infra. RTA.: Ok, ya me fijo para preparar las correcciones enseguida 28/7/2026: Se envìa por Email, las Observaciones a corregir por el municipio. 17/7/2026: Se solicita informen si pudieron avanzar con la documentaciòn. Respuesta: me faltan unos datos técnicos que tiene q mandar el ingeniero y le enviamos todo juntos 19/6/26: El municipio presenta documentación a corregir y completar. Se envía INSTRUCTIVO de la documentación legal y técnica requerida.El 26/05/2026 se logra la comunicación telefónica con el Intendente. Se le envía documentación modelo por WhatsApp | D7: =IFERROR(VLOOKUP($A7,'Base TOTAL'!A:AU,34,0), "-") -> 46168 | E7: =IFERROR(VLOOKUP($A7,'Base TOTAL'!A:AU,35,0), "-") -> DIRECCION DE JURISDICCION DE REGULARIZACION DE OBRAS Y PROYECTOS
A8: =IFERROR(__xludf.DUMMYFUNCTION("""COMPUTED_VALUE"""),"Capitán General Bernardo O'Higgins") -> Capitán General Bernardo O'Higgins | B8: =IFERROR(VLOOKUP($A8,'Base TOTAL'!A:AU,2,0), "-") -> Marcos Juárez | C8: =IFERROR(VLOOKUP($A8,'Base TOTAL'!A:AU,33,0), "-") -> 20/8/2026: Se envìa mensaje a la Int. preguntando si pudieron completar la documentaciòn. 28/7/2026: Se envìan por Email Observaciones a corregir por la comuna, al arq. e infra. RTA de arq. P. Lapentta: Hola... Bien! Habia visto esos detalles pero pense que con lo que presentaba era suficiente. Ya los completaré. 23/7/2026: Comunicaciòn con el arq. para corregir las observaciones. Se envìa Email con Instructivo. 22/7/2026: Se envìan por Email las observaciones a corregir por el M-C 13/7/2026: Presentan nuevamente la documentaciòn En evaluaciòn areas legal y tècnica. 25-6-26: Comunicaciòn con int. y arq. para completen Georeferencia. 19/6/2026 se envian observaciones por email para corregir y completar. 18/6/26: Comunicación con el municipio para enviar Instructivo. EL 16/04/26 SE CONTACTÓ A LA INTENDENTE. EL 29/04/26 NOS VISITÓ Y CONSULTÓ. VA A ENVIAR DOCUMENTACIÓN | D8: =IFERROR(VLOOKUP($A8,'Base TOTAL'!A:AU,34,0), "-") -> 46126 | E8: =IFERROR(VLOOKUP($A8,'Base TOTAL'!A:AU,35,0), "-") -> DIRECCION DE JURISDICCION DE REGULARIZACION DE OBRAS Y PROYECTOS
A9: =IFERROR(__xludf.DUMMYFUNCTION("""COMPUTED_VALUE"""),"El Arañado") -> El Arañado | B9: =IFERROR(VLOOKUP($A9,'Base TOTAL'!A:AU,2,0), "-") -> San Justo | C9: =IFERROR(VLOOKUP($A9,'Base TOTAL'!A:AU,33,0), "-") -> 20/8/2026: Se envía por Email, el Instructivo con el cambio de denominación. (Hoy Secretaría) 05/8/2026: Comunicaciòn con M/C enviando correo electrònico. 24/6/26:Comunicación con el municipio. Se envía Instructivo de la documentación legal y técnica requerida. 5/6/26: Ingresa Nota Ministerio Gobierno autorizando financiamiento. | D9: =IFERROR(VLOOKUP($A9,'Base TOTAL'!A:AU,34,0), "-") -> 46178 | E9: =IFERROR(VLOOKUP($A9,'Base TOTAL'!A:AU,35,0), "-") -> DIRECCION DE JURISDICCION DE REGULARIZACION DE OBRAS Y PROYECTOS
A10: =IFERROR(__xludf.DUMMYFUNCTION("""COMPUTED_VALUE"""),"General Baldissera") -> General Baldissera | B10: =IFERROR(VLOOKUP($A10,'Base TOTAL'!A:AU,2,0), "-") -> Marcos Juárez | C10: =IFERROR(VLOOKUP($A10,'Base TOTAL'!A:AU,33,0), "-") -> 27/8/2026: Se envian Observaciones a corregir x mail al intend.+ profes. + infra. 26/8/2026: Se recibe doc. 24/8/2026: Se re envian Observac. para corregir por Mail al int + profes + Infra 20/8/2026: Se envìa mensaje al Int. preguntando si pudieron corregir la documentaciòn para presentar. 05/8/2026: Se envían por Email Observaciones a corregir por el municipio. 24/6/26: Se envía Instructivo de documentación legal y técnica requerida. 22/6/26: Se solicitan correos electrònicos del municipio y profesional a cargo. El 11/5/26 se logra comunicación con municipalidad. Se pasa por whatsapp la documentación modelo | D10: =IFERROR(VLOOKUP($A10,'Base TOTAL'!A:AU,34,0), "-") -> 46150 | E10: =IFERROR(VLOOKUP($A10,'Base TOTAL'!A:AU,35,0), "-") -> DIRECCION DE JURISDICCION DE REGULARIZACION DE OBRAS Y PROYECTOS
A11: =IFERROR(__xludf.DUMMYFUNCTION("""COMPUTED_VALUE"""),"Guanaco Muerto") -> Guanaco Muerto | B11: =IFERROR(VLOOKUP($A11,'Base TOTAL'!A:AU,2,0), "-") -> Cruz del Eje | C11: =IFERROR(VLOOKUP($A11,'Base TOTAL'!A:AU,33,0), "-") -> 03/9/2026: Se reciben actualiz. por mail del presid. comunal (se avisa x whatss que el monto del computo debe coincidir con el monto total autoriz) 31/8/2026: Se re envian correcc al Presid. Com + prof. + infra x mail 26/8/2026: Se reitera nuevamente al ing. Bracamonte x mail la la correccion antes solicitada de agregar el ITems pto. 1,3 al computo y demas doc. derivadas del mismo 25/8/2026: Presentan actualiz. 21/8/2026: Se reitera el pedido de correcciones. 14/8/2026: Se responde Mail al ing. solicitando item1.3 en Computo y Avance.. 10/8/2026: Se envìa x mail Observaciones a corregir por presid. Comunal + profes. + infra 07/8/2026: Presentan nuevamente docum. a evaluar 05/8/2026: La Comuna tenìa una consulta para el àrea Legal, se les pregunto y se enviò la respuesta. Se aguarda la documentaciòn corregida. 04/8/2026: Se solicita a la comuna informen si pudieron corregir la documentaciòn. 22/7/2026: Se envìan Observaciones A corregir por Comuna 20/7/2026: Se recibe documentaciòn el 17/7. En evaluaciòn area Legales. 18/6/26: Se envìa Instructivo de documentaciòn legal y tècnica a presentar por M-C. EL 29/04/26 SE LE ENVÍA LOS REQUISITOS, VA A ENVIAR DOCUMENTACIÓN Completó el punto 4. Se le envió el 29/04/26 los restantes items para completar Expte. | D11: =IFERROR(VLOOKUP($A11,'Base TOTAL'!A:AU,34,0), "-") -> 46126 | E11: =IFERROR(VLOOKUP($A11,'Base TOTAL'!A:AU,35,0), "-") -> DIRECCION DE JURISDICCION DE REGULARIZACION DE OBRAS Y PROYECTOS
A12: =IFERROR(__xludf.DUMMYFUNCTION("""COMPUTED_VALUE"""),"Los Reartes") -> Los Reartes | B12: =IFERROR(VLOOKUP($A12,'Base TOTAL'!A:AU,2,0), "-") -> Calamuchita | C12: =IFERROR(VLOOKUP($A12,'Base TOTAL'!A:AU,33,0), "-") -> 31/8/2026: Se recibe doc. actualiz. x mail 24/8/2026: Se envìan Observac. p/compl. o correg. por Mail a la Presid. Com. + prof. + infra. 11/8/2026: Se recibem actualiz. por mail 07/8/2026: Se envian por Email Observaciones a corregir por intend. + prof. + Infra. Se reciben doc. 04/8/2026: Se envìan x mail correcc. al intend. + profes + infra Se recibe doc. Tècn. 03/8/2026: El ing. de la Comuna solicita Instructivo para hacer las correcciones en la doc. presentada. 27/7/2026: Se les consulto por email sobre las observaciones a la documentacion presentada. 17/7/2026: Se envìan por Email las observaciones A corregir por la comuna 15/7/2026: Fri Jul 03 2026 04:00:00 GMT-0300 (Argentina Standard Time) 03/7/2026: Presentan documentación en evaluaciòn. 22/6/26:Comunicaciòn con la pres. comunal. Se envìa Instructivo de la documentaciòn legal y tècnica requerida al munic. y al profesional. . 5/6/26: Ingresa Nota Ministerio Gobierno autorizando financiamiento. | D12: =IFERROR(VLOOKUP($A12,'Base TOTAL'!A:AU,34,0), "-") -> 46178 | E12: =IFERROR(VLOOKUP($A12,'Base TOTAL'!A:AU,35,0), "-") -> DIRECCION DE JURISDICCION DE REGULARIZACION DE OBRAS Y PROYECTOS
A13: =IFERROR(__xludf.DUMMYFUNCTION("""COMPUTED_VALUE"""),"Manfredi") -> Manfredi | B13: =IFERROR(VLOOKUP($A13,'Base TOTAL'!A:AU,2,0), "-") -> Río Segundo | C13: =IFERROR(VLOOKUP($A13,'Base TOTAL'!A:AU,33,0), "-") -> 02/9/2026: Se envian Observaciones a corregir al Intendente + Profes. + infra. 20/8/2026: Se envìan por Email las Observaciones A corregir por M. 20/8/2026: Se envìan por Email las Observaciones A corregir por M. 19/8/2026: El int. envìa documentaciòn tècnica por wathsapp. En evaluaciòn. 05/8/2026: Comunicaciòn con M/C enviando correo electrònico. 23/7/2026: Se envìa Email con la Notificaciòn ya enviada por Cidi el 3/7/2026. 23/7/2026: Comunicaciòn con el int. se solicita correos electrònicos para enviar Instructivo. | D13: =IFERROR(VLOOKUP($A13,'Base TOTAL'!A:AU,34,0), "-") | E13: =IFERROR(VLOOKUP($A13,'Base TOTAL'!A:AU,35,0), "-")
A14: =IFERROR(__xludf.DUMMYFUNCTION("""COMPUTED_VALUE"""),"Rosales") -> Rosales | B14: =IFERROR(VLOOKUP($A14,'Base TOTAL'!A:AU,2,0), "-") -> Presidente Roque Sáenz Peña | C14: =IFERROR(VLOOKUP($A14,'Base TOTAL'!A:AU,33,0), "-") -> 04/9/2026: Se re envian Observaciones p/corregir x mail a intend. + prof. + infra. 20/08/2026 Se solicita por Whatss, actualiz. doc. al ing. Rodrigues -RTAS.: ....... 04/8/2026: Se reitera el pedido de documetnaciòn al ing. encargado. 28/7/2026: Respuesta: "estamos a la espera de que el ingeniero pueda realizar las observaciones. Apenas lo tengamos se lo pasamos." 27/7/2026: se consulto por email el estado de las observaciones al legajo técnico. 16/7/2026: El municipio corrige la doc. legal pero falta que corrija la doc. tècnica. 15/7/2026: Se envían al municipio y profesional, las Observaciones a corregir. 07/7/2026: Envìan contacto y correo electrònico del ing. a cargo de la obra. 24/6/26: Se enviò Instructivo .El 8/05/26 se envió documentación modelo para participar. El 11/ envió documentación a analizar | D14: =IFERROR(VLOOKUP($A14,'Base TOTAL'!A:AU,34,0), "-") -> 46126 | E14: =IFERROR(VLOOKUP($A14,'Base TOTAL'!A:AU,35,0), "-") -> DIRECCION DE JURISDICCION DE REGULARIZACION DE OBRAS Y PROYECTOS
A15: =IFERROR(__xludf.DUMMYFUNCTION("""COMPUTED_VALUE"""),"Sacanta") -> Sacanta | B15: =IFERROR(VLOOKUP($A15,'Base TOTAL'!A:AU,2,0), "-") -> San Justo | C15: =IFERROR(VLOOKUP($A15,'Base TOTAL'!A:AU,33,0), "-") -> 04/9/2026: Se envìan al arq. encargado las Observaciones A corregir. 20/8/2026: Se envìan por Email las Observaciones A corregir por el Munic. 03/8/2026: Se envìan correcc a intend. Secr tec e Infraestr. 29/6/2026: Se envía nuevamente al municipio (Email) el Instructivo de la documentación legal y técnica requerida. 24/6/26: El Intendente informa que el monto autorizado es de $100 mill. y no $70 como dice la autorización previa. Ya hizo la gestión para que corrijan. /// Se envía Instructivo de la documentación legal y técnica a presentar.....23/6/26: Comunicaciòn con municipio solicitando Correo electrònico. 5/6/26: Ingresa Nota Ministerio Gobierno autorizando financiamiento. | D15: =IFERROR(VLOOKUP($A15,'Base TOTAL'!A:AU,34,0), "-") -> 46178 | E15: =IFERROR(VLOOKUP($A15,'Base TOTAL'!A:AU,35,0), "-") -> DIRECCION DE JURISDICCION DE REGULARIZACION DE OBRAS Y PROYECTOS
A16: =IFERROR(__xludf.DUMMYFUNCTION("""COMPUTED_VALUE"""),"San Joaquín") -> San Joaquín | B16: =IFERROR(VLOOKUP($A16,'Base TOTAL'!A:AU,2,0), "-") -> Presidente Roque Sáenz Peña | C16: =IFERROR(VLOOKUP($A16,'Base TOTAL'!A:AU,33,0), "-") -> 28/8/2026: Se reciben actualizac. 21/8/2026: Se re-envian por whatss las Observac. a correg a la nva profes. 21/08/2026: Se reciben actualiz. x el Presid. Comunal x whatss del A.Legal y se confecciona la planilla de Observ. para anexar cuando la nva prof. envie actualiz. Tecnicas. 20/8/2026: Se envìa mensaje al Int. preguntando si pudieron corregir las Observaciones para presentar la documentaciòn. 29/7/2026: Se envìa Planilla de Observ. a corregir por la comuna , al nvo profesional y a Infraestr. 28/7/2026: El municipio cambiò de profesional. Se le envìa el instructivo a la nueva arq. 22/7/2026: Se envìa nuevamente al Email las observaciones A corregir por la comuna 22/7/2026: El 14/7/2026 presentan documentaciòn a corregir nuevamente. 25/6/26: Comunicación con int. solicitando presenten correcciones. Se espera respuesta de la ing. a cargo. 19/6/26: Comunicaciòn con la ing. a cargo . Se solcita la presentaciòn a la mayor brevedad posible . 12-06-2026 Solicitar P Georef en Planim. + demas doc.Tec y leg 11/6/26: Se solicita nuevamente la correcciòn de Documentaciòn tècnica.Tiene todos los Items completos, salvo por el 4 (documentación técnica). El 29/5/26 se reclama la documentación firmada EL 19/05/26 PRESENTA PROYECTO CORREGIDO (A EVALUAR). EL 30/4 PRESENTAN NUEVO PRESUPUESTO, A VALOR $30.000.000. DEBE FUNDAMENTAR EL INCREMENTO EN EL MONTO TOTAL EL CÓMPUTO. El 30/04 se recibe y el monto que presenta es menor que el que se le da. Se pide que lo haga llegar al monto asignado El 28/04/26 se le envía documentación técnica modelo. EL 20/04/2026 LA COMUNA ENVÍA DOCUMENTACIÓN. FALTA INFO TÉCNICA. PRESENTA PRESUPUESTO, DE $21.969.370 - FALTA FIRMAS DE ÉSTE. EL 14/04/26 SE CONTACTÓ AL PRESIDENTE COMUNAL - | D16: =IFERROR(VLOOKUP($A16,'Base TOTAL'!A:AU,34,0), "-") -> 46199 | E16: =IFERROR(VLOOKUP($A16,'Base TOTAL'!A:AU,35,0), "-") -> DIRECCION DE JURISDICCION ECONOMICO, FINANCIERA Y DE ADMINISTRACION
A17: =IFERROR(__xludf.DUMMYFUNCTION("""COMPUTED_VALUE"""),"Tío Pujio") -> Tío Pujio | B17: =IFERROR(VLOOKUP($A17,'Base TOTAL'!A:AU,2,0), "-") -> General San Martín | C17: =IFERROR(VLOOKUP($A17,'Base TOTAL'!A:AU,33,0), "-") -> 02/9/2026: Se enviaron Observac. p/ corregir a Munic. + profes. + infra 01/09/2026: Se reciben actualiz. x mail 25/8/2026: Se envìan por Email las Observaciones tècnicas A corregir por el M. 24/8/2026: Se esperan observaciones del area legales para enviar al m. 18/8/2026: Presentan documetnaciòn por Email En evaluaciòn. 13/8/2026: Se recibe doc. y se responden por whatss consultas s/ la prosecuc. de los mismos 03/8/2026: Comunicaciòn con el encargado de la obra. Se envìa Instructivo para preparar toda la documentaciòn. 24/7/2026: Comunicaciòn con int. Se enviò Instructivo . | D17: =IFERROR(VLOOKUP($A17,'Base TOTAL'!A:AU,34,0), "-") | E17: =IFERROR(VLOOKUP($A17,'Base TOTAL'!A:AU,35,0), "-")
A18: =IFERROR(__xludf.DUMMYFUNCTION("""COMPUTED_VALUE"""),"Villa del Prado") -> Villa del Prado | B18: =IFERROR(VLOOKUP($A18,'Base TOTAL'!A:AU,2,0), "-") -> Santa María | C18: =IFERROR(VLOOKUP($A18,'Base TOTAL'!A:AU,33,0), "-") -> 02/9/2026: Se envìa a la comuna las Observaciones A corregir. 20/8/2026: Se envìa por Email, el Instructivo con el cambio de denominaciòn. (Hoy Secretarìa) 22/6/26: Se envìa Instructivo de la documentaciòn legal y tècnica requerida. 19/6/25/6/26: Comunicaciòn con el int. Se solicita correo electrònico para enviar instructivo. 5/6/26: Ingresa Nota Ministerio Gobierno autorizando financiamiento. | D18: =IFERROR(VLOOKUP($A18,'Base TOTAL'!A:AU,34,0), "-") -> 46178 | E18: =IFERROR(VLOOKUP($A18,'Base TOTAL'!A:AU,35,0), "-") -> DIRECCION DE JURISDICCION DE REGULARIZACION DE OBRAS Y PROYECTOS
B19: =IFERROR(VLOOKUP($A19,'Base TOTAL'!A:AU,2,0), "-") -> - | C19: =IFERROR(VLOOKUP($A19,'Base TOTAL'!A:AU,33,0), "-") -> - | D19: =IFERROR(VLOOKUP($A19,'Base TOTAL'!A:AU,34,0), "-") -> - | E19: =IFERROR(VLOOKUP($A19,'Base TOTAL'!A:AU,35,0), "-") -> -
B20: =IFERROR(VLOOKUP($A20,'Base TOTAL'!A:AU,2,0), "-") -> - | C20: =IFERROR(VLOOKUP($A20,'Base TOTAL'!A:AU,33,0), "-") -> - | D20: =IFERROR(VLOOKUP($A20,'Base TOTAL'!A:AU,34,0), "-") -> - | E20: =IFERROR(VLOOKUP($A20,'Base TOTAL'!A:AU,35,0), "-") -> -
B21: =IFERROR(VLOOKUP($A21,'Base TOTAL'!A:AU,2,0), "-") -> - | C21: =IFERROR(VLOOKUP($A21,'Base TOTAL'!A:AU,33,0), "-") -> - | D21: =IFERROR(VLOOKUP($A21,'Base TOTAL'!A:AU,34,0), "-") -> - | E21: =IFERROR(VLOOKUP($A21,'Base TOTAL'!A:AU,35,0), "-") -> -
B22: =IFERROR(VLOOKUP($A22,'Base TOTAL'!A:AU,2,0), "-") -> - | C22: =IFERROR(VLOOKUP($A22,'Base TOTAL'!A:AU,33,0), "-") -> - | D22: =IFERROR(VLOOKUP($A22,'Base TOTAL'!A:AU,34,0), "-") -> - | E22: =IFERROR(VLOOKUP($A22,'Base TOTAL'!A:AU,35,0), "-") -> -
B23: =IFERROR(VLOOKUP($A23,'Base TOTAL'!A:AU,2,0), "-") -> - | C23: =IFERROR(VLOOKUP($A23,'Base TOTAL'!A:AU,33,0), "-") -> - | D23: =IFERROR(VLOOKUP($A23,'Base TOTAL'!A:AU,34,0), "-") -> - | E23: =IFERROR(VLOOKUP($A23,'Base TOTAL'!A:AU,35,0), "-") -> -
B24: =IFERROR(VLOOKUP($A24,'Base TOTAL'!A:AU,2,0), "-") -> - | C24: =IFERROR(VLOOKUP($A24,'Base TOTAL'!A:AU,33,0), "-") -> - | D24: =IFERROR(VLOOKUP($A24,'Base TOTAL'!A:AU,34,0), "-") -> - | E24: =IFERROR(VLOOKUP($A24,'Base TOTAL'!A:AU,35,0), "-") -> -
B25: =IFERROR(VLOOKUP($A25,'Base TOTAL'!A:AU,2,0), "-") -> - | C25: =IFERROR(VLOOKUP($A25,'Base TOTAL'!A:AU,33,0), "-") -> - | D25: =IFERROR(VLOOKUP($A25,'Base TOTAL'!A:AU,34,0), "-") -> - | E25: =IFERROR(VLOOKUP($A25,'Base TOTAL'!A:AU,35,0), "-") -> -
B26: =IFERROR(VLOOKUP($A26,'Base TOTAL'!A:AU,2,0), "-") -> - | C26: =IFERROR(VLOOKUP($A26,'Base TOTAL'!A:AU,33,0), "-") -> - | D26: =IFERROR(VLOOKUP($A26,'Base TOTAL'!A:AU,34,0), "-") -> - | E26: =IFERROR(VLOOKUP($A26,'Base TOTAL'!A:AU,35,0), "-") -> -
B27: =IFERROR(VLOOKUP($A27,'Base TOTAL'!A:AU,2,0), "-") -> - | C27: =IFERROR(VLOOKUP($A27,'Base TOTAL'!A:AU,33,0), "-") -> - | D27: =IFERROR(VLOOKUP($A27,'Base TOTAL'!A:AU,34,0), "-") -> - | E27: =IFERROR(VLOOKUP($A27,'Base TOTAL'!A:AU,35,0), "-") -> -
B28: =IFERROR(VLOOKUP($A28,'Base TOTAL'!A:AU,2,0), "-") -> - | C28: =IFERROR(VLOOKUP($A28,'Base TOTAL'!A:AU,33,0), "-") -> - | D28: =IFERROR(VLOOKUP($A28,'Base TOTAL'!A:AU,34,0), "-") -> - | E28: =IFERROR(VLOOKUP($A28,'Base TOTAL'!A:AU,35,0), "-") -> -
B29: =IFERROR(VLOOKUP($A29,'Base TOTAL'!A:AU,2,0), "-") -> - | C29: =IFERROR(VLOOKUP($A29,'Base TOTAL'!A:AU,33,0), "-") -> - | D29: =IFERROR(VLOOKUP($A29,'Base TOTAL'!A:AU,34,0), "-") -> - | E29: =IFERROR(VLOOKUP($A29,'Base TOTAL'!A:AU,35,0), "-") -> -
B30: =IFERROR(VLOOKUP($A30,'Base TOTAL'!A:AU,2,0), "-") -> - | C30: =IFERROR(VLOOKUP($A30,'Base TOTAL'!A:AU,33,0), "-") -> - | D30: =IFERROR(VLOOKUP($A30,'Base TOTAL'!A:AU,34,0), "-") -> - | E30: =IFERROR(VLOOKUP($A30,'Base TOTAL'!A:AU,35,0), "-") -> -
... B501: =IFERROR(VLOOKUP($A501,'Base TOTAL'!A:AU,2,0), "-") -> - | C501: =IFERROR(VLOOKUP($A501,'Base TOTAL'!A:AU,33,0), "-") -> - | D501: =IFERROR(VLOOKUP($A501,'Base TOTAL'!A:AU,34,0), "-") -> - | E501: =IFERROR(VLOOKUP($A501,'Base TOTAL'!A:AU,35,0), "-") -> -

Sheet REP CH estado exp.
A1: OBRA: "CÓRDOBA HOGAR"
A2: PROGRAMA: "CÓRDOBA HOGAR"
A3: REPORTE | B3: =TODAY() -> 46269
A4: ='Base TOTAL'!AF2 -> ESTADO DEL EXPEDIENTE DE LA LOCALIDAD | C4: COMPLETO en TÉCNICA
C5: =COUNTIF(C7:C400, "<>-") -> 2 | D5: ='Base TOTAL'!AH2 -> EXP en FECHA
A6: Localidad | B6: Departamento | C6: ='Base TOTAL'!AG2 -> OBSERVACIONES | D6: ='Base TOTAL'!AH2 -> EXP en FECHA | E6: ='Base TOTAL'!AI2 -> EXP en REPARTICIÓN
A7: =IFERROR(__xludf.DUMMYFUNCTION("SORT(FILTER('Base TOTAL'!A:A, 'Base TOTAL'!BM:BM = C4))"),"Charras") -> Charras | B7: =IFERROR(VLOOKUP($A7,'Base TOTAL'!A:AU,2,0), "-") -> Juárez Celman | C7: =IFERROR(VLOOKUP($A7,'Base TOTAL'!A:AU,33,0), "-") -> 20/7/2026: PASA A LEGALES para prosecuciòn del tràmite. 16/7/2026: Presentan otra correcciòn observada por legales. 03/7/2026: Presentan documentaciòn nuevamente. 01/7/2026: Se envìan al municipio /profesional las Observaciones a corregir. 30-06-2026 Avisa el int. que envìo doc. por mail 18/6/26: Se envìa Instructivo de documentaciòn legal y tècnica a presentar por M-C. P -17-06-2026 Se corrige envio y se envia por whats al Intend. Emiliano p/ su completam. -RTAS.: 12/6/26: Comunicaciòn con Intendente para dar inicio al tràmite. 5/6/26: Ingresa Nota Ministerio Gobierno autorizando financiamiento. | D7: =IFERROR(VLOOKUP($A7,'Base TOTAL'!A:AU,34,0), "-") -> 46224 | E7: =IFERROR(VLOOKUP($A7,'Base TOTAL'!A:AU,35,0), "-") -> DIRECCION DE JURISDICCION LEGAL Y NOTARIAL
A8: =IFERROR(__xludf.DUMMYFUNCTION("""COMPUTED_VALUE"""),"El Fortín") -> El Fortín | B8: =IFERROR(VLOOKUP($A8,'Base TOTAL'!A:AU,2,0), "-") -> San Justo | C8: =IFERROR(VLOOKUP($A8,'Base TOTAL'!A:AU,33,0), "-") -> 20/8/2026: Se envía por Email, el Instructivo con el cambio de denominación. (Hoy Secretaría) 05/8/2026: Comunicaciòn con M/C enviando correo electrònico. 29/6/2026: Comunicación con el intendenten. Se envía el Instructivo al arquitecto a cargo 18/6/26: Se envìa Instructivo de documentaciòn legal y tècnica a presentar por M-C. 8/6/26: Se envía Instructivo (Doc. Requerida) a la localidad. 5/6/26: Ingresa Nota Ministerio Gobierno | D8: =IFERROR(VLOOKUP($A8,'Base TOTAL'!A:AU,34,0), "-") -> 46178 | E8: =IFERROR(VLOOKUP($A8,'Base TOTAL'!A:AU,35,0), "-") -> DIRECCION DE JURISDICCION DE REGULARIZACION DE OBRAS Y PROYECTOS
B9: =IFERROR(VLOOKUP($A9,'Base TOTAL'!A:AU,2,0), "-") -> - | C9: =IFERROR(VLOOKUP($A9,'Base TOTAL'!A:AU,33,0), "-") -> - | D9: =IFERROR(VLOOKUP($A9,'Base TOTAL'!A:AU,34,0), "-") -> - | E9: =IFERROR(VLOOKUP($A9,'Base TOTAL'!A:AU,35,0), "-") -> -
B10: =IFERROR(VLOOKUP($A10,'Base TOTAL'!A:AU,2,0), "-") -> - | C10: =IFERROR(VLOOKUP($A10,'Base TOTAL'!A:AU,33,0), "-") -> - | D10: =IFERROR(VLOOKUP($A10,'Base TOTAL'!A:AU,34,0), "-") -> - | E10: =IFERROR(VLOOKUP($A10,'Base TOTAL'!A:AU,35,0), "-") -> -
B11: =IFERROR(VLOOKUP($A11,'Base TOTAL'!A:AU,2,0), "-") -> - | C11: =IFERROR(VLOOKUP($A11,'Base TOTAL'!A:AU,33,0), "-") -> - | D11: =IFERROR(VLOOKUP($A11,'Base TOTAL'!A:AU,34,0), "-") -> - | E11: =IFERROR(VLOOKUP($A11,'Base TOTAL'!A:AU,35,0), "-") -> -
B12: =IFERROR(VLOOKUP($A12,'Base TOTAL'!A:AU,2,0), "-") -> - | C12: =IFERROR(VLOOKUP($A12,'Base TOTAL'!A:AU,33,0), "-") -> - | D12: =IFERROR(VLOOKUP($A12,'Base TOTAL'!A:AU,34,0), "-") -> - | E12: =IFERROR(VLOOKUP($A12,'Base TOTAL'!A:AU,35,0), "-") -> -
B13: =IFERROR(VLOOKUP($A13,'Base TOTAL'!A:AU,2,0), "-") -> - | C13: =IFERROR(VLOOKUP($A13,'Base TOTAL'!A:AU,33,0), "-") -> - | D13: =IFERROR(VLOOKUP($A13,'Base TOTAL'!A:AU,34,0), "-") -> - | E13: =IFERROR(VLOOKUP($A13,'Base TOTAL'!A:AU,35,0), "-") -> -
B14: =IFERROR(VLOOKUP($A14,'Base TOTAL'!A:AU,2,0), "-") -> - | C14: =IFERROR(VLOOKUP($A14,'Base TOTAL'!A:AU,33,0), "-") -> - | D14: =IFERROR(VLOOKUP($A14,'Base TOTAL'!A:AU,34,0), "-") -> - | E14: =IFERROR(VLOOKUP($A14,'Base TOTAL'!A:AU,35,0), "-") -> -
B15: =IFERROR(VLOOKUP($A15,'Base TOTAL'!A:AU,2,0), "-") -> - | C15: =IFERROR(VLOOKUP($A15,'Base TOTAL'!A:AU,33,0), "-") -> - | D15: =IFERROR(VLOOKUP($A15,'Base TOTAL'!A:AU,34,0), "-") -> - | E15: =IFERROR(VLOOKUP($A15,'Base TOTAL'!A:AU,35,0), "-") -> -
B16: =IFERROR(VLOOKUP($A16,'Base TOTAL'!A:AU,2,0), "-") -> - | C16: =IFERROR(VLOOKUP($A16,'Base TOTAL'!A:AU,33,0), "-") -> - | D16: =IFERROR(VLOOKUP($A16,'Base TOTAL'!A:AU,34,0), "-") -> - | E16: =IFERROR(VLOOKUP($A16,'Base TOTAL'!A:AU,35,0), "-") -> -
B17: =IFERROR(VLOOKUP($A17,'Base TOTAL'!A:AU,2,0), "-") -> - | C17: =IFERROR(VLOOKUP($A17,'Base TOTAL'!A:AU,33,0), "-") -> - | D17: =IFERROR(VLOOKUP($A17,'Base TOTAL'!A:AU,34,0), "-") -> - | E17: =IFERROR(VLOOKUP($A17,'Base TOTAL'!A:AU,35,0), "-") -> -
B18: =IFERROR(VLOOKUP($A18,'Base TOTAL'!A:AU,2,0), "-") -> - | C18: =IFERROR(VLOOKUP($A18,'Base TOTAL'!A:AU,33,0), "-") -> - | D18: =IFERROR(VLOOKUP($A18,'Base TOTAL'!A:AU,34,0), "-") -> - | E18: =IFERROR(VLOOKUP($A18,'Base TOTAL'!A:AU,35,0), "-") -> -
B19: =IFERROR(VLOOKUP($A19,'Base TOTAL'!A:AU,2,0), "-") -> - | C19: =IFERROR(VLOOKUP($A19,'Base TOTAL'!A:AU,33,0), "-") -> - | D19: =IFERROR(VLOOKUP($A19,'Base TOTAL'!A:AU,34,0), "-") -> - | E19: =IFERROR(VLOOKUP($A19,'Base TOTAL'!A:AU,35,0), "-") -> -
B20: =IFERROR(VLOOKUP($A20,'Base TOTAL'!A:AU,2,0), "-") -> - | C20: =IFERROR(VLOOKUP($A20,'Base TOTAL'!A:AU,33,0), "-") -> - | D20: =IFERROR(VLOOKUP($A20,'Base TOTAL'!A:AU,34,0), "-") -> - | E20: =IFERROR(VLOOKUP($A20,'Base TOTAL'!A:AU,35,0), "-") -> -
... B501: =IFERROR(VLOOKUP($A501,'Base TOTAL'!A:AU,2,0), "-") -> - | C501: =IFERROR(VLOOKUP($A501,'Base TOTAL'!A:AU,33,0), "-") -> - | D501: =IFERROR(VLOOKUP($A501,'Base TOTAL'!A:AU,34,0), "-") -> - | E501: =IFERROR(VLOOKUP($A501,'Base TOTAL'!A:AU,35,0), "-") -> -

Sheet REP CC ubicacion exp.
A1: OBRA: "EJECUCIÒN DE CORDÒN CUNETA Y ADOQUINADO"
A2: PROGRAMA: "PROVINCIAL DE CORDÒN CUNETA Y ADOQUINES" - LEY Nº 11.089
A3: REPORTE | B3: =TODAY() -> 46269
A4: =#REF! -> #REF! | C4: DIRECCION DE JURISDICCION ECONOMICO, FINANCIERA Y DE ADMINISTRACION
C5: =COUNTIF(C7:C400, "<>-") -> 3 | D5: INGRESO | E5: ='Base TOTAL'!AF2 -> ESTADO DEL EXPEDIENTE DE LA LOCALIDAD
A6: Localidad | B6: Departamento | D6: ='Base TOTAL'!AH2 -> EXP en FECHA | E6: ESTADO
A7: =IFERROR(__xludf.DUMMYFUNCTION("SORT(FILTER('Base TOTAL'!A:A, 'Base TOTAL'!AI:AI = C4))"),"La Higuera") -> La Higuera | B7: =IFERROR(VLOOKUP($A7,'Base TOTAL'!A:AU,2,0), "-") -> Cruz del Eje | C7: =IFERROR(VLOOKUP($A7,'Base TOTAL'!A:AU,33,0), "-") -> 12/8/2026: El Secretario consulta s/la doc. enviada y se avisa que PASO A LEGALES el 29-07 para su prosecuciòn 29/7/2026: PASA A LEGALES para prosecuciòn del tràmite. 22/7/2026: Se envìa PLA. Observaciones a corregir. 22/7/2026: Presentan documentaciòn a evaluar. 21/7/2026: Escriben consultando por el Email. Se solicita Correo electrònico 13-07-2026 Se llamo al ing. quien avisa que hoy envia doc. a la firma de la comuna y mañana nos envian por mail. 13/7/2026: Se solicita a la comuna y al ing. informen si puedieron avanzar con la documentaciòn. 13/7/2026: Se solicita a la comuna y al ing. informen si puedieron avanzar con la documentaciòn. 30-06-2026 Se reitera actualiz y completar docum. s/ instr. 26/6/2026: holaaaaaa 26/6/26: Se solicita al Ing. que complete la documentaciòn requerida conforme al Instructivo. 24/6/26: Se insiste y se hace un llamado al pres. comunal. Envìa datos por wathsapp. 22/6/26: Se solicita correo electrònico y datos del profesional para enviar instructivo. Sin respuesta 12-05-2026 Se envia las correcciones de la documentac. tecnica y la nota inial ( via whatsapp a Gonzalo Guzman El 30/04/2026 envían documentación de los items 1 a 5 para ver EL MARTES 28/04/26 SE HABLÓ POR TELÉFONO Y POR WHATSAPP, DONDE SE LE ENVIÓ LOS 9 PUNTOS Y SE COMPROMETIÓ EN DAR RESPUESTA. | D7: =IFERROR(VLOOKUP($A7,'Base TOTAL'!A:AU,34,0), "-") -> 46245 | E7: =IFERROR(VLOOKUP($A7,'Base TOTAL'!A:AU,32,0), "-") -> COMPLETO en TÉCNICA
A8: =IFERROR(__xludf.DUMMYFUNCTION("""COMPUTED_VALUE"""),"San Joaquín") -> San Joaquín | B8: =IFERROR(VLOOKUP($A8,'Base TOTAL'!A:AU,2,0), "-") -> Presidente Roque Sáenz Peña | C8: =IFERROR(VLOOKUP($A8,'Base TOTAL'!A:AU,33,0), "-") -> 28/8/2026: Se reciben actualizac. 21/8/2026: Se re-envian por whatss las Observac. a correg a la nva profes. 21/08/2026: Se reciben actualiz. x el Presid. Comunal x whatss del A.Legal y se confecciona la planilla de Observ. para anexar cuando la nva prof. envie actualiz. Tecnicas. 20/8/2026: Se envìa mensaje al Int. preguntando si pudieron corregir las Observaciones para presentar la documentaciòn. 29/7/2026: Se envìa Planilla de Observ. a corregir por la comuna , al nvo profesional y a Infraestr. 28/7/2026: El municipio cambiò de profesional. Se le envìa el instructivo a la nueva arq. 22/7/2026: Se envìa nuevamente al Email las observaciones A corregir por la comuna 22/7/2026: El 14/7/2026 presentan documentaciòn a corregir nuevamente. 25/6/26: Comunicación con int. solicitando presenten correcciones. Se espera respuesta de la ing. a cargo. 19/6/26: Comunicaciòn con la ing. a cargo . Se solcita la presentaciòn a la mayor brevedad posible . 12-06-2026 Solicitar P Georef en Planim. + demas doc.Tec y leg 11/6/26: Se solicita nuevamente la correcciòn de Documentaciòn tècnica.Tiene todos los Items completos, salvo por el 4 (documentación técnica). El 29/5/26 se reclama la documentación firmada EL 19/05/26 PRESENTA PROYECTO CORREGIDO (A EVALUAR). EL 30/4 PRESENTAN NUEVO PRESUPUESTO, A VALOR $30.000.000. DEBE FUNDAMENTAR EL INCREMENTO EN EL MONTO TOTAL EL CÓMPUTO. El 30/04 se recibe y el monto que presenta es menor que el que se le da. Se pide que lo haga llegar al monto asignado El 28/04/26 se le envía documentación técnica modelo. EL 20/04/2026 LA COMUNA ENVÍA DOCUMENTACIÓN. FALTA INFO TÉCNICA. PRESENTA PRESUPUESTO, DE $21.969.370 - FALTA FIRMAS DE ÉSTE. EL 14/04/26 SE CONTACTÓ AL PRESIDENTE COMUNAL - | D8: =IFERROR(VLOOKUP($A8,'Base TOTAL'!A:AU,34,0), "-") -> 46199 | E8: =IFERROR(VLOOKUP($A8,'Base TOTAL'!A:AU,32,0), "-") -> En CURSO en TÉCNICA
